[2023-01-28 04:27:22,412] {taskinstance.py:1032} INFO - Dependencies all met for <TaskInstance: data_ingestion_fhv_dag.bq_fhv_external_table_task scheduled__2019-03-01T00:00:00+00:00 [queued]>
[2023-01-28 04:27:22,425] {taskinstance.py:1032} INFO - Dependencies all met for <TaskInstance: data_ingestion_fhv_dag.bq_fhv_external_table_task scheduled__2019-03-01T00:00:00+00:00 [queued]>
[2023-01-28 04:27:22,426] {taskinstance.py:1238} INFO - 
--------------------------------------------------------------------------------
[2023-01-28 04:27:22,428] {taskinstance.py:1239} INFO - Starting attempt 2 of 3
[2023-01-28 04:27:22,429] {taskinstance.py:1240} INFO - 
--------------------------------------------------------------------------------
[2023-01-28 04:27:22,443] {taskinstance.py:1259} INFO - Executing <Task(BigQueryCreateExternalTableOperator): bq_fhv_external_table_task> on 2019-03-01 00:00:00+00:00
[2023-01-28 04:27:22,449] {standard_task_runner.py:52} INFO - Started process 25846 to run task
[2023-01-28 04:27:22,454] {standard_task_runner.py:76} INFO - Running: ['***', 'tasks', 'run', 'data_ingestion_fhv_dag', 'bq_fhv_external_table_task', 'scheduled__2019-03-01T00:00:00+00:00', '--job-id', '207', '--raw', '--subdir', 'DAGS_FOLDER/data_ingestion_fhv_dag.py', '--cfg-path', '/tmp/tmpbky7dpig', '--error-file', '/tmp/tmpro3in27d']
[2023-01-28 04:27:22,456] {standard_task_runner.py:77} INFO - Job 207: Subtask bq_fhv_external_table_task
[2023-01-28 04:27:22,529] {logging_mixin.py:109} INFO - Running <TaskInstance: data_ingestion_fhv_dag.bq_fhv_external_table_task scheduled__2019-03-01T00:00:00+00:00 [running]> on host adbf820de9e6
[2023-01-28 04:27:22,582] {logging_mixin.py:109} WARNING - /home/***/.local/lib/python3.7/site-packages/***/utils/context.py:152 AirflowContextDeprecationWarning: Accessing 'execution_date' from the template is deprecated and will be removed in a future version. Please use 'data_interval_start' or 'logical_date' instead.
[2023-01-28 04:27:22,615] {taskinstance.py:1426} INFO - Exporting the following env vars:
AIRFLOW_CTX_DAG_OWNER=***
AIRFLOW_CTX_DAG_ID=data_ingestion_fhv_dag
AIRFLOW_CTX_TASK_ID=bq_fhv_external_table_task
AIRFLOW_CTX_EXECUTION_DATE=2019-03-01T00:00:00+00:00
AIRFLOW_CTX_DAG_RUN_ID=scheduled__2019-03-01T00:00:00+00:00
[2023-01-28 04:27:22,618] {crypto.py:82} WARNING - empty cryptography key - values will not be stored encrypted.
[2023-01-28 04:27:23,920] {taskinstance.py:1700} ERROR - Task failed with exception
Traceback (most recent call last):
  File "/home/airflow/.local/lib/python3.7/site-packages/airflow/models/taskinstance.py", line 1329, in _run_raw_task
    self._execute_task_with_callbacks(context)
  File "/home/airflow/.local/lib/python3.7/site-packages/airflow/models/taskinstance.py", line 1455, in _execute_task_with_callbacks
    result = self._execute_task(context, self.task)
  File "/home/airflow/.local/lib/python3.7/site-packages/airflow/models/taskinstance.py", line 1511, in _execute_task
    result = execute_callable(context=context)
  File "/home/airflow/.local/lib/python3.7/site-packages/airflow/providers/google/cloud/operators/bigquery.py", line 1196, in execute
    table_resource=self.table_resource,
  File "/home/airflow/.local/lib/python3.7/site-packages/airflow/providers/google/common/hooks/base_google.py", line 430, in inner_wrapper
    return func(self, *args, **kwargs)
  File "/home/airflow/.local/lib/python3.7/site-packages/airflow/providers/google/cloud/hooks/bigquery.py", line 408, in create_empty_table
    table=table, exists_ok=exists_ok, retry=retry
  File "/home/airflow/.local/lib/python3.7/site-packages/google/cloud/bigquery/client.py", line 755, in create_table
    timeout=timeout,
  File "/home/airflow/.local/lib/python3.7/site-packages/google/cloud/bigquery/client.py", line 782, in _call_api
    return call()
  File "/home/airflow/.local/lib/python3.7/site-packages/google/api_core/retry.py", line 291, in retry_wrapped_func
    on_error=on_error,
  File "/home/airflow/.local/lib/python3.7/site-packages/google/api_core/retry.py", line 189, in retry_target
    return target()
  File "/home/airflow/.local/lib/python3.7/site-packages/google/cloud/_http.py", line 484, in api_request
    raise exceptions.from_http_response(response)
google.api_core.exceptions.BadRequest: 400 POST https://bigquery.googleapis.com/bigquery/v2/projects/ny-rides-kelvin/datasets/trips_data_all/tables?prettyPrint=false: Error while reading table: fhv2019-03_external_table, error message: Failed to expand table fhv2019-03_external_table with file pattern gs://dtc_data_lake_ny-rides-kelvin/raw/fhv_tripdata_2019-03: matched no files. File: gs://dtc_data_lake_ny-rides-kelvin/raw/fhv_tripdata_2019-03
[2023-01-28 04:27:23,961] {taskinstance.py:1277} INFO - Marking task as UP_FOR_RETRY. dag_id=data_ingestion_fhv_dag, task_id=bq_fhv_external_table_task, execution_date=20190301T000000, start_date=20230128T042722, end_date=20230128T042723
[2023-01-28 04:27:24,006] {standard_task_runner.py:92} ERROR - Failed to execute job 207 for task bq_fhv_external_table_task
Traceback (most recent call last):
  File "/home/airflow/.local/lib/python3.7/site-packages/airflow/task/task_runner/standard_task_runner.py", line 85, in _start_by_fork
    args.func(args, dag=self.dag)
  File "/home/airflow/.local/lib/python3.7/site-packages/airflow/cli/cli_parser.py", line 48, in command
    return func(*args, **kwargs)
  File "/home/airflow/.local/lib/python3.7/site-packages/airflow/utils/cli.py", line 92, in wrapper
    return f(*args, **kwargs)
  File "/home/airflow/.local/lib/python3.7/site-packages/airflow/cli/commands/task_command.py", line 298, in task_run
    _run_task_by_selected_method(args, dag, ti)
  File "/home/airflow/.local/lib/python3.7/site-packages/airflow/cli/commands/task_command.py", line 107, in _run_task_by_selected_method
    _run_raw_task(args, ti)
  File "/home/airflow/.local/lib/python3.7/site-packages/airflow/cli/commands/task_command.py", line 184, in _run_raw_task
    error_file=args.error_file,
  File "/home/airflow/.local/lib/python3.7/site-packages/airflow/utils/session.py", line 70, in wrapper
    return func(*args, session=session, **kwargs)
  File "/home/airflow/.local/lib/python3.7/site-packages/airflow/models/taskinstance.py", line 1329, in _run_raw_task
    self._execute_task_with_callbacks(context)
  File "/home/airflow/.local/lib/python3.7/site-packages/airflow/models/taskinstance.py", line 1455, in _execute_task_with_callbacks
    result = self._execute_task(context, self.task)
  File "/home/airflow/.local/lib/python3.7/site-packages/airflow/models/taskinstance.py", line 1511, in _execute_task
    result = execute_callable(context=context)
  File "/home/airflow/.local/lib/python3.7/site-packages/airflow/providers/google/cloud/operators/bigquery.py", line 1196, in execute
    table_resource=self.table_resource,
  File "/home/airflow/.local/lib/python3.7/site-packages/airflow/providers/google/common/hooks/base_google.py", line 430, in inner_wrapper
    return func(self, *args, **kwargs)
  File "/home/airflow/.local/lib/python3.7/site-packages/airflow/providers/google/cloud/hooks/bigquery.py", line 408, in create_empty_table
    table=table, exists_ok=exists_ok, retry=retry
  File "/home/airflow/.local/lib/python3.7/site-packages/google/cloud/bigquery/client.py", line 755, in create_table
    timeout=timeout,
  File "/home/airflow/.local/lib/python3.7/site-packages/google/cloud/bigquery/client.py", line 782, in _call_api
    return call()
  File "/home/airflow/.local/lib/python3.7/site-packages/google/api_core/retry.py", line 291, in retry_wrapped_func
    on_error=on_error,
  File "/home/airflow/.local/lib/python3.7/site-packages/google/api_core/retry.py", line 189, in retry_target
    return target()
  File "/home/airflow/.local/lib/python3.7/site-packages/google/cloud/_http.py", line 484, in api_request
    raise exceptions.from_http_response(response)
google.api_core.exceptions.BadRequest: 400 POST https://bigquery.googleapis.com/bigquery/v2/projects/ny-rides-kelvin/datasets/trips_data_all/tables?prettyPrint=false: Error while reading table: fhv2019-03_external_table, error message: Failed to expand table fhv2019-03_external_table with file pattern gs://dtc_data_lake_ny-rides-kelvin/raw/fhv_tripdata_2019-03: matched no files. File: gs://dtc_data_lake_ny-rides-kelvin/raw/fhv_tripdata_2019-03
[2023-01-28 04:27:24,056] {local_task_job.py:154} INFO - Task exited with return code 1
[2023-01-28 04:27:24,095] {local_task_job.py:264} INFO - 0 downstream tasks scheduled from follow-on schedule check
