[2023-01-24 02:29:52,661] {taskinstance.py:1032} INFO - Dependencies all met for <TaskInstance: LocalIngestionDag.ingest manual__2023-01-24T02:29:25.270855+00:00 [queued]>
[2023-01-24 02:29:52,674] {taskinstance.py:1032} INFO - Dependencies all met for <TaskInstance: LocalIngestionDag.ingest manual__2023-01-24T02:29:25.270855+00:00 [queued]>
[2023-01-24 02:29:52,675] {taskinstance.py:1238} INFO - 
--------------------------------------------------------------------------------
[2023-01-24 02:29:52,675] {taskinstance.py:1239} INFO - Starting attempt 1 of 1
[2023-01-24 02:29:52,675] {taskinstance.py:1240} INFO - 
--------------------------------------------------------------------------------
[2023-01-24 02:29:52,692] {taskinstance.py:1259} INFO - Executing <Task(BashOperator): ingest> on 2023-01-24 02:29:25.270855+00:00
[2023-01-24 02:29:52,707] {standard_task_runner.py:52} INFO - Started process 5660 to run task
[2023-01-24 02:29:52,714] {standard_task_runner.py:76} INFO - Running: ['***', 'tasks', 'run', 'LocalIngestionDag', 'ingest', 'manual__2023-01-24T02:29:25.270855+00:00', '--job-id', '61', '--raw', '--subdir', 'DAGS_FOLDER/data_ingestion_local.py', '--cfg-path', '/tmp/tmpjmfj61p7', '--error-file', '/tmp/tmp9woi332q']
[2023-01-24 02:29:52,715] {standard_task_runner.py:77} INFO - Job 61: Subtask ingest
[2023-01-24 02:29:52,796] {logging_mixin.py:109} INFO - Running <TaskInstance: LocalIngestionDag.ingest manual__2023-01-24T02:29:25.270855+00:00 [running]> on host 6018d13d82e3
[2023-01-24 02:29:52,868] {taskinstance.py:1426} INFO - Exporting the following env vars:
AIRFLOW_CTX_DAG_OWNER=***
AIRFLOW_CTX_DAG_ID=LocalIngestionDag
AIRFLOW_CTX_TASK_ID=ingest
AIRFLOW_CTX_EXECUTION_DATE=2023-01-24T02:29:25.270855+00:00
AIRFLOW_CTX_DAG_RUN_ID=manual__2023-01-24T02:29:25.270855+00:00
[2023-01-24 02:29:52,870] {subprocess.py:62} INFO - Tmp dir root location: 
 /tmp
[2023-01-24 02:29:52,871] {subprocess.py:74} INFO - Running command: ['bash', '-c', 'ls {AIRFLOW_HOME}']
[2023-01-24 02:29:52,884] {subprocess.py:85} INFO - Output:
[2023-01-24 02:29:52,889] {subprocess.py:89} INFO - ls: cannot access '{AIRFLOW_HOME}': No such file or directory
[2023-01-24 02:29:52,890] {subprocess.py:93} INFO - Command exited with return code 2
[2023-01-24 02:29:52,907] {taskinstance.py:1700} ERROR - Task failed with exception
Traceback (most recent call last):
  File "/home/airflow/.local/lib/python3.7/site-packages/airflow/models/taskinstance.py", line 1329, in _run_raw_task
    self._execute_task_with_callbacks(context)
  File "/home/airflow/.local/lib/python3.7/site-packages/airflow/models/taskinstance.py", line 1455, in _execute_task_with_callbacks
    result = self._execute_task(context, self.task)
  File "/home/airflow/.local/lib/python3.7/site-packages/airflow/models/taskinstance.py", line 1511, in _execute_task
    result = execute_callable(context=context)
  File "/home/airflow/.local/lib/python3.7/site-packages/airflow/operators/bash.py", line 188, in execute
    f'Bash command failed. The command returned a non-zero exit code {result.exit_code}.'
airflow.exceptions.AirflowException: Bash command failed. The command returned a non-zero exit code 2.
[2023-01-24 02:29:52,917] {taskinstance.py:1277} INFO - Marking task as FAILED. dag_id=LocalIngestionDag, task_id=ingest, execution_date=20230124T022925, start_date=20230124T022952, end_date=20230124T022952
[2023-01-24 02:29:52,937] {standard_task_runner.py:92} ERROR - Failed to execute job 61 for task ingest
Traceback (most recent call last):
  File "/home/airflow/.local/lib/python3.7/site-packages/airflow/task/task_runner/standard_task_runner.py", line 85, in _start_by_fork
    args.func(args, dag=self.dag)
  File "/home/airflow/.local/lib/python3.7/site-packages/airflow/cli/cli_parser.py", line 48, in command
    return func(*args, **kwargs)
  File "/home/airflow/.local/lib/python3.7/site-packages/airflow/utils/cli.py", line 92, in wrapper
    return f(*args, **kwargs)
  File "/home/airflow/.local/lib/python3.7/site-packages/airflow/cli/commands/task_command.py", line 298, in task_run
    _run_task_by_selected_method(args, dag, ti)
  File "/home/airflow/.local/lib/python3.7/site-packages/airflow/cli/commands/task_command.py", line 107, in _run_task_by_selected_method
    _run_raw_task(args, ti)
  File "/home/airflow/.local/lib/python3.7/site-packages/airflow/cli/commands/task_command.py", line 184, in _run_raw_task
    error_file=args.error_file,
  File "/home/airflow/.local/lib/python3.7/site-packages/airflow/utils/session.py", line 70, in wrapper
    return func(*args, session=session, **kwargs)
  File "/home/airflow/.local/lib/python3.7/site-packages/airflow/models/taskinstance.py", line 1329, in _run_raw_task
    self._execute_task_with_callbacks(context)
  File "/home/airflow/.local/lib/python3.7/site-packages/airflow/models/taskinstance.py", line 1455, in _execute_task_with_callbacks
    result = self._execute_task(context, self.task)
  File "/home/airflow/.local/lib/python3.7/site-packages/airflow/models/taskinstance.py", line 1511, in _execute_task
    result = execute_callable(context=context)
  File "/home/airflow/.local/lib/python3.7/site-packages/airflow/operators/bash.py", line 188, in execute
    f'Bash command failed. The command returned a non-zero exit code {result.exit_code}.'
airflow.exceptions.AirflowException: Bash command failed. The command returned a non-zero exit code 2.
[2023-01-24 02:29:53,010] {local_task_job.py:154} INFO - Task exited with return code 1
[2023-01-24 02:29:53,051] {local_task_job.py:264} INFO - 0 downstream tasks scheduled from follow-on schedule check
