[2023-01-29 12:27:46,793] {taskinstance.py:1032} INFO - Dependencies all met for <TaskInstance: data_ingestion_gcs_dag.cast_parquet_columns_task scheduled__2019-02-01T00:00:00+00:00 [queued]>
[2023-01-29 12:27:46,807] {taskinstance.py:1032} INFO - Dependencies all met for <TaskInstance: data_ingestion_gcs_dag.cast_parquet_columns_task scheduled__2019-02-01T00:00:00+00:00 [queued]>
[2023-01-29 12:27:46,808] {taskinstance.py:1238} INFO - 
--------------------------------------------------------------------------------
[2023-01-29 12:27:46,809] {taskinstance.py:1239} INFO - Starting attempt 6 of 7
[2023-01-29 12:27:46,810] {taskinstance.py:1240} INFO - 
--------------------------------------------------------------------------------
[2023-01-29 12:27:46,822] {taskinstance.py:1259} INFO - Executing <Task(PythonOperator): cast_parquet_columns_task> on 2019-02-01 00:00:00+00:00
[2023-01-29 12:27:46,827] {standard_task_runner.py:52} INFO - Started process 4360 to run task
[2023-01-29 12:27:46,831] {standard_task_runner.py:76} INFO - Running: ['***', 'tasks', 'run', 'data_ingestion_gcs_dag', 'cast_parquet_columns_task', 'scheduled__2019-02-01T00:00:00+00:00', '--job-id', '366', '--raw', '--subdir', 'DAGS_FOLDER/data_ingestion_gcs_dag.py', '--cfg-path', '/tmp/tmpf14eyfp_', '--error-file', '/tmp/tmpeqs17lkj']
[2023-01-29 12:27:46,832] {standard_task_runner.py:77} INFO - Job 366: Subtask cast_parquet_columns_task
[2023-01-29 12:27:46,888] {logging_mixin.py:109} INFO - Running <TaskInstance: data_ingestion_gcs_dag.cast_parquet_columns_task scheduled__2019-02-01T00:00:00+00:00 [running]> on host 2530f37057aa
[2023-01-29 12:27:46,933] {logging_mixin.py:109} WARNING - /home/***/.local/lib/python3.7/site-packages/***/utils/context.py:152 AirflowContextDeprecationWarning: Accessing 'execution_date' from the template is deprecated and will be removed in a future version. Please use 'data_interval_start' or 'logical_date' instead.
[2023-01-29 12:27:46,950] {taskinstance.py:1426} INFO - Exporting the following env vars:
AIRFLOW_CTX_DAG_OWNER=***
AIRFLOW_CTX_DAG_ID=data_ingestion_gcs_dag
AIRFLOW_CTX_TASK_ID=cast_parquet_columns_task
AIRFLOW_CTX_EXECUTION_DATE=2019-02-01T00:00:00+00:00
AIRFLOW_CTX_DAG_RUN_ID=scheduled__2019-02-01T00:00:00+00:00
[2023-01-29 12:27:46,952] {logging_mixin.py:109} INFO - /opt/***
[2023-01-29 12:27:47,110] {logging_mixin.py:109} WARNING - --- Logging error ---
[2023-01-29 12:27:47,114] {logging_mixin.py:109} WARNING - Traceback (most recent call last):
[2023-01-29 12:27:47,116] {logging_mixin.py:109} WARNING -   File "/usr/local/lib/python3.7/logging/__init__.py", line 1025, in emit
    msg = self.format(record)
[2023-01-29 12:27:47,117] {logging_mixin.py:109} WARNING -   File "/usr/local/lib/python3.7/logging/__init__.py", line 869, in format
    return fmt.format(record)
[2023-01-29 12:27:47,119] {logging_mixin.py:109} WARNING -   File "/usr/local/lib/python3.7/logging/__init__.py", line 608, in format
    record.message = record.getMessage()
[2023-01-29 12:27:47,120] {logging_mixin.py:109} WARNING -   File "/usr/local/lib/python3.7/logging/__init__.py", line 369, in getMessage
    msg = msg % self.args
[2023-01-29 12:27:47,122] {logging_mixin.py:109} WARNING - TypeError: not all arguments converted during string formatting
[2023-01-29 12:27:47,123] {logging_mixin.py:109} WARNING - Call stack:
[2023-01-29 12:27:47,169] {logging_mixin.py:109} WARNING -   File "/home/***/.local/bin/***", line 8, in <module>
    sys.exit(main())
[2023-01-29 12:27:47,171] {logging_mixin.py:109} WARNING -   File "/home/***/.local/lib/python3.7/site-packages/***/__main__.py", line 48, in main
    args.func(args)
[2023-01-29 12:27:47,177] {logging_mixin.py:109} WARNING -   File "/home/***/.local/lib/python3.7/site-packages/***/cli/cli_parser.py", line 48, in command
    return func(*args, **kwargs)
[2023-01-29 12:27:47,178] {logging_mixin.py:109} WARNING -   File "/home/***/.local/lib/python3.7/site-packages/***/utils/cli.py", line 92, in wrapper
    return f(*args, **kwargs)
[2023-01-29 12:27:47,180] {logging_mixin.py:109} WARNING -   File "/home/***/.local/lib/python3.7/site-packages/***/cli/commands/scheduler_command.py", line 75, in scheduler
    _run_scheduler_job(args=args)
[2023-01-29 12:27:47,183] {logging_mixin.py:109} WARNING -   File "/home/***/.local/lib/python3.7/site-packages/***/cli/commands/scheduler_command.py", line 46, in _run_scheduler_job
    job.run()
[2023-01-29 12:27:47,184] {logging_mixin.py:109} WARNING -   File "/home/***/.local/lib/python3.7/site-packages/***/jobs/base_job.py", line 245, in run
    self._execute()
[2023-01-29 12:27:47,185] {logging_mixin.py:109} WARNING -   File "/home/***/.local/lib/python3.7/site-packages/***/jobs/scheduler_job.py", line 620, in _execute
    self.executor.start()
[2023-01-29 12:27:47,186] {logging_mixin.py:109} WARNING -   File "/home/***/.local/lib/python3.7/site-packages/***/executors/local_executor.py", line 356, in start
    self.impl.start()
[2023-01-29 12:27:47,188] {logging_mixin.py:109} WARNING -   File "/home/***/.local/lib/python3.7/site-packages/***/executors/local_executor.py", line 298, in start
    worker.start()
[2023-01-29 12:27:47,190] {logging_mixin.py:109} WARNING -   File "/usr/local/lib/python3.7/multiprocessing/process.py", line 112, in start
    self._popen = self._Popen(self)
[2023-01-29 12:27:47,191] {logging_mixin.py:109} WARNING -   File "/usr/local/lib/python3.7/multiprocessing/context.py", line 223, in _Popen
    return _default_context.get_context().Process._Popen(process_obj)
[2023-01-29 12:27:47,193] {logging_mixin.py:109} WARNING -   File "/usr/local/lib/python3.7/multiprocessing/context.py", line 277, in _Popen
    return Popen(process_obj)
[2023-01-29 12:27:47,195] {logging_mixin.py:109} WARNING -   File "/usr/local/lib/python3.7/multiprocessing/popen_fork.py", line 20, in __init__
    self._launch(process_obj)
[2023-01-29 12:27:47,197] {logging_mixin.py:109} WARNING -   File "/usr/local/lib/python3.7/multiprocessing/popen_fork.py", line 74, in _launch
    code = process_obj._bootstrap()
[2023-01-29 12:27:47,198] {logging_mixin.py:109} WARNING -   File "/usr/local/lib/python3.7/multiprocessing/process.py", line 297, in _bootstrap
    self.run()
[2023-01-29 12:27:47,200] {logging_mixin.py:109} WARNING -   File "/home/***/.local/lib/python3.7/site-packages/***/executors/local_executor.py", line 67, in run
    return super().run()
[2023-01-29 12:27:47,201] {logging_mixin.py:109} WARNING -   File "/usr/local/lib/python3.7/multiprocessing/process.py", line 99, in run
    self._target(*self._args, **self._kwargs)
[2023-01-29 12:27:47,203] {logging_mixin.py:109} WARNING -   File "/home/***/.local/lib/python3.7/site-packages/***/executors/local_executor.py", line 190, in do_work
    self.execute_work(key=key, command=command)
[2023-01-29 12:27:47,205] {logging_mixin.py:109} WARNING -   File "/home/***/.local/lib/python3.7/site-packages/***/executors/local_executor.py", line 84, in execute_work
    state = self._execute_work_in_fork(command)
[2023-01-29 12:27:47,206] {logging_mixin.py:109} WARNING -   File "/home/***/.local/lib/python3.7/site-packages/***/executors/local_executor.py", line 124, in _execute_work_in_fork
    args.func(args)
[2023-01-29 12:27:47,207] {logging_mixin.py:109} WARNING -   File "/home/***/.local/lib/python3.7/site-packages/***/cli/cli_parser.py", line 48, in command
    return func(*args, **kwargs)
[2023-01-29 12:27:47,208] {logging_mixin.py:109} WARNING -   File "/home/***/.local/lib/python3.7/site-packages/***/utils/cli.py", line 92, in wrapper
    return f(*args, **kwargs)
[2023-01-29 12:27:47,210] {logging_mixin.py:109} WARNING -   File "/home/***/.local/lib/python3.7/site-packages/***/cli/commands/task_command.py", line 298, in task_run
    _run_task_by_selected_method(args, dag, ti)
[2023-01-29 12:27:47,211] {logging_mixin.py:109} WARNING -   File "/home/***/.local/lib/python3.7/site-packages/***/cli/commands/task_command.py", line 105, in _run_task_by_selected_method
    _run_task_by_local_task_job(args, ti)
[2023-01-29 12:27:47,213] {logging_mixin.py:109} WARNING -   File "/home/***/.local/lib/python3.7/site-packages/***/cli/commands/task_command.py", line 163, in _run_task_by_local_task_job
    run_job.run()
[2023-01-29 12:27:47,215] {logging_mixin.py:109} WARNING -   File "/home/***/.local/lib/python3.7/site-packages/***/jobs/base_job.py", line 245, in run
    self._execute()
[2023-01-29 12:27:47,216] {logging_mixin.py:109} WARNING -   File "/home/***/.local/lib/python3.7/site-packages/***/jobs/local_task_job.py", line 103, in _execute
    self.task_runner.start()
[2023-01-29 12:27:47,217] {logging_mixin.py:109} WARNING -   File "/home/***/.local/lib/python3.7/site-packages/***/task/task_runner/standard_task_runner.py", line 41, in start
    self.process = self._start_by_fork()
[2023-01-29 12:27:47,218] {logging_mixin.py:109} WARNING -   File "/home/***/.local/lib/python3.7/site-packages/***/task/task_runner/standard_task_runner.py", line 85, in _start_by_fork
    args.func(args, dag=self.dag)
[2023-01-29 12:27:47,220] {logging_mixin.py:109} WARNING -   File "/home/***/.local/lib/python3.7/site-packages/***/cli/cli_parser.py", line 48, in command
    return func(*args, **kwargs)
[2023-01-29 12:27:47,221] {logging_mixin.py:109} WARNING -   File "/home/***/.local/lib/python3.7/site-packages/***/utils/cli.py", line 92, in wrapper
    return f(*args, **kwargs)
[2023-01-29 12:27:47,222] {logging_mixin.py:109} WARNING -   File "/home/***/.local/lib/python3.7/site-packages/***/cli/commands/task_command.py", line 298, in task_run
    _run_task_by_selected_method(args, dag, ti)
[2023-01-29 12:27:47,223] {logging_mixin.py:109} WARNING -   File "/home/***/.local/lib/python3.7/site-packages/***/cli/commands/task_command.py", line 107, in _run_task_by_selected_method
    _run_raw_task(args, ti)
[2023-01-29 12:27:47,225] {logging_mixin.py:109} WARNING -   File "/home/***/.local/lib/python3.7/site-packages/***/cli/commands/task_command.py", line 184, in _run_raw_task
    error_file=args.error_file,
[2023-01-29 12:27:47,225] {logging_mixin.py:109} WARNING -   File "/home/***/.local/lib/python3.7/site-packages/***/utils/session.py", line 70, in wrapper
    return func(*args, session=session, **kwargs)
[2023-01-29 12:27:47,226] {logging_mixin.py:109} WARNING -   File "/home/***/.local/lib/python3.7/site-packages/***/models/taskinstance.py", line 1329, in _run_raw_task
    self._execute_task_with_callbacks(context)
[2023-01-29 12:27:47,227] {logging_mixin.py:109} WARNING -   File "/home/***/.local/lib/python3.7/site-packages/***/models/taskinstance.py", line 1455, in _execute_task_with_callbacks
    result = self._execute_task(context, self.task)
[2023-01-29 12:27:47,228] {logging_mixin.py:109} WARNING -   File "/home/***/.local/lib/python3.7/site-packages/***/models/taskinstance.py", line 1511, in _execute_task
    result = execute_callable(context=context)
[2023-01-29 12:27:47,229] {logging_mixin.py:109} WARNING -   File "/home/***/.local/lib/python3.7/site-packages/***/operators/python.py", line 174, in execute
    return_value = self.execute_callable()
[2023-01-29 12:27:47,230] {logging_mixin.py:109} WARNING -   File "/home/***/.local/lib/python3.7/site-packages/***/operators/python.py", line 185, in execute_callable
    return self.python_callable(*self.op_args, **self.op_kwargs)
[2023-01-29 12:27:47,231] {logging_mixin.py:109} WARNING -   File "/opt/***/dags/data_ingestion_gcs_dag.py", line 64, in cast_parquet_columns
    logging.info('table', table)
[2023-01-29 12:27:47,232] {logging_mixin.py:109} WARNING -   File "/usr/local/lib/python3.7/logging/__init__.py", line 1992, in info
    root.info(msg, *args, **kwargs)
[2023-01-29 12:27:47,233] {logging_mixin.py:109} WARNING -   File "/usr/local/lib/python3.7/logging/__init__.py", line 1378, in info
    self._log(INFO, msg, args, **kwargs)
[2023-01-29 12:27:47,234] {logging_mixin.py:109} WARNING -   File "/usr/local/lib/python3.7/logging/__init__.py", line 1514, in _log
    self.handle(record)
[2023-01-29 12:27:47,234] {logging_mixin.py:109} WARNING -   File "/usr/local/lib/python3.7/logging/__init__.py", line 1524, in handle
    self.callHandlers(record)
[2023-01-29 12:27:47,235] {logging_mixin.py:109} WARNING -   File "/usr/local/lib/python3.7/logging/__init__.py", line 1586, in callHandlers
    hdlr.handle(record)
[2023-01-29 12:27:47,237] {logging_mixin.py:109} WARNING -   File "/usr/local/lib/python3.7/logging/__init__.py", line 894, in handle
    self.emit(record)
[2023-01-29 12:27:47,238] {logging_mixin.py:109} WARNING -   File "/home/***/.local/lib/python3.7/site-packages/***/utils/log/file_task_handler.py", line 67, in emit
    self.handler.emit(record)
[2023-01-29 12:27:47,240] {logging_mixin.py:109} WARNING - Message: 'table'
Arguments: (pyarrow.Table
dispatching_base_num: string
pickup_datetime: timestamp[s]
dropOff_datetime: timestamp[s]
PUlocationID: int64
DOlocationID: int64
SR_Flag: int64
Affiliated_base_number: string,)
[2023-01-29 12:27:47,242] {taskinstance.py:1700} ERROR - Task failed with exception
Traceback (most recent call last):
  File "/home/airflow/.local/lib/python3.7/site-packages/airflow/models/taskinstance.py", line 1329, in _run_raw_task
    self._execute_task_with_callbacks(context)
  File "/home/airflow/.local/lib/python3.7/site-packages/airflow/models/taskinstance.py", line 1455, in _execute_task_with_callbacks
    result = self._execute_task(context, self.task)
  File "/home/airflow/.local/lib/python3.7/site-packages/airflow/models/taskinstance.py", line 1511, in _execute_task
    result = execute_callable(context=context)
  File "/home/airflow/.local/lib/python3.7/site-packages/airflow/operators/python.py", line 174, in execute
    return_value = self.execute_callable()
  File "/home/airflow/.local/lib/python3.7/site-packages/airflow/operators/python.py", line 185, in execute_callable
    return self.python_callable(*self.op_args, **self.op_kwargs)
  File "/opt/airflow/dags/data_ingestion_gcs_dag.py", line 65, in cast_parquet_columns
    pq.write_table(table, dataset_file.replace('.parquet', '_casted.parquet'))
  File "/home/airflow/.local/lib/python3.7/site-packages/pyarrow/parquet.py", line 1986, in write_table
    **kwargs) as writer:
  File "/home/airflow/.local/lib/python3.7/site-packages/pyarrow/parquet.py", line 638, in __init__
    where, filesystem, allow_legacy_filesystem=True
  File "/home/airflow/.local/lib/python3.7/site-packages/pyarrow/fs.py", line 174, in _resolve_filesystem_and_path
    filesystem, path = FileSystem.from_uri(path)
  File "pyarrow/_fs.pyx", line 347, in pyarrow._fs.FileSystem.from_uri
  File "pyarrow/error.pxi", line 143, in pyarrow.lib.pyarrow_internal_check_status
  File "pyarrow/error.pxi", line 99, in pyarrow.lib.check_status
pyarrow.lib.ArrowInvalid: Cannot parse URI: 'fhv_tripdata_{{ execution_date.strftime('%Y-%m') }}_casted.parquet'
[2023-01-29 12:27:47,258] {taskinstance.py:1277} INFO - Marking task as UP_FOR_RETRY. dag_id=data_ingestion_gcs_dag, task_id=cast_parquet_columns_task, execution_date=20190201T000000, start_date=20230129T122746, end_date=20230129T122747
[2023-01-29 12:27:47,312] {standard_task_runner.py:92} ERROR - Failed to execute job 366 for task cast_parquet_columns_task
Traceback (most recent call last):
  File "/home/airflow/.local/lib/python3.7/site-packages/airflow/task/task_runner/standard_task_runner.py", line 85, in _start_by_fork
    args.func(args, dag=self.dag)
  File "/home/airflow/.local/lib/python3.7/site-packages/airflow/cli/cli_parser.py", line 48, in command
    return func(*args, **kwargs)
  File "/home/airflow/.local/lib/python3.7/site-packages/airflow/utils/cli.py", line 92, in wrapper
    return f(*args, **kwargs)
  File "/home/airflow/.local/lib/python3.7/site-packages/airflow/cli/commands/task_command.py", line 298, in task_run
    _run_task_by_selected_method(args, dag, ti)
  File "/home/airflow/.local/lib/python3.7/site-packages/airflow/cli/commands/task_command.py", line 107, in _run_task_by_selected_method
    _run_raw_task(args, ti)
  File "/home/airflow/.local/lib/python3.7/site-packages/airflow/cli/commands/task_command.py", line 184, in _run_raw_task
    error_file=args.error_file,
  File "/home/airflow/.local/lib/python3.7/site-packages/airflow/utils/session.py", line 70, in wrapper
    return func(*args, session=session, **kwargs)
  File "/home/airflow/.local/lib/python3.7/site-packages/airflow/models/taskinstance.py", line 1329, in _run_raw_task
    self._execute_task_with_callbacks(context)
  File "/home/airflow/.local/lib/python3.7/site-packages/airflow/models/taskinstance.py", line 1455, in _execute_task_with_callbacks
    result = self._execute_task(context, self.task)
  File "/home/airflow/.local/lib/python3.7/site-packages/airflow/models/taskinstance.py", line 1511, in _execute_task
    result = execute_callable(context=context)
  File "/home/airflow/.local/lib/python3.7/site-packages/airflow/operators/python.py", line 174, in execute
    return_value = self.execute_callable()
  File "/home/airflow/.local/lib/python3.7/site-packages/airflow/operators/python.py", line 185, in execute_callable
    return self.python_callable(*self.op_args, **self.op_kwargs)
  File "/opt/airflow/dags/data_ingestion_gcs_dag.py", line 65, in cast_parquet_columns
    pq.write_table(table, dataset_file.replace('.parquet', '_casted.parquet'))
  File "/home/airflow/.local/lib/python3.7/site-packages/pyarrow/parquet.py", line 1986, in write_table
    **kwargs) as writer:
  File "/home/airflow/.local/lib/python3.7/site-packages/pyarrow/parquet.py", line 638, in __init__
    where, filesystem, allow_legacy_filesystem=True
  File "/home/airflow/.local/lib/python3.7/site-packages/pyarrow/fs.py", line 174, in _resolve_filesystem_and_path
    filesystem, path = FileSystem.from_uri(path)
  File "pyarrow/_fs.pyx", line 347, in pyarrow._fs.FileSystem.from_uri
  File "pyarrow/error.pxi", line 143, in pyarrow.lib.pyarrow_internal_check_status
  File "pyarrow/error.pxi", line 99, in pyarrow.lib.check_status
pyarrow.lib.ArrowInvalid: Cannot parse URI: 'fhv_tripdata_{{ execution_date.strftime('%Y-%m') }}_casted.parquet'
[2023-01-29 12:27:47,369] {local_task_job.py:154} INFO - Task exited with return code 1
[2023-01-29 12:27:47,407] {local_task_job.py:264} INFO - 0 downstream tasks scheduled from follow-on schedule check
