[2023-01-29 06:19:29,446] {taskinstance.py:1032} INFO - Dependencies all met for <TaskInstance: data_ingestion_fhv_dag.bq_create_fhv_partitioned_clustered_table_task scheduled__2019-02-01T00:00:00+00:00 [queued]>
[2023-01-29 06:19:29,458] {taskinstance.py:1032} INFO - Dependencies all met for <TaskInstance: data_ingestion_fhv_dag.bq_create_fhv_partitioned_clustered_table_task scheduled__2019-02-01T00:00:00+00:00 [queued]>
[2023-01-29 06:19:29,459] {taskinstance.py:1238} INFO - 
--------------------------------------------------------------------------------
[2023-01-29 06:19:29,460] {taskinstance.py:1239} INFO - Starting attempt 1 of 2
[2023-01-29 06:19:29,460] {taskinstance.py:1240} INFO - 
--------------------------------------------------------------------------------
[2023-01-29 06:19:29,473] {taskinstance.py:1259} INFO - Executing <Task(BigQueryInsertJobOperator): bq_create_fhv_partitioned_clustered_table_task> on 2019-02-01 00:00:00+00:00
[2023-01-29 06:19:29,478] {standard_task_runner.py:52} INFO - Started process 41346 to run task
[2023-01-29 06:19:29,482] {standard_task_runner.py:76} INFO - Running: ['***', 'tasks', 'run', 'data_ingestion_fhv_dag', 'bq_create_fhv_partitioned_clustered_table_task', 'scheduled__2019-02-01T00:00:00+00:00', '--job-id', '248', '--raw', '--subdir', 'DAGS_FOLDER/data_ingestion_fhv_dag.py', '--cfg-path', '/tmp/tmpkfcjnib6', '--error-file', '/tmp/tmpmg63c6ns']
[2023-01-29 06:19:29,485] {standard_task_runner.py:77} INFO - Job 248: Subtask bq_create_fhv_partitioned_clustered_table_task
[2023-01-29 06:19:29,549] {logging_mixin.py:109} INFO - Running <TaskInstance: data_ingestion_fhv_dag.bq_create_fhv_partitioned_clustered_table_task scheduled__2019-02-01T00:00:00+00:00 [running]> on host adbf820de9e6
[2023-01-29 06:19:29,612] {taskinstance.py:1426} INFO - Exporting the following env vars:
AIRFLOW_CTX_DAG_OWNER=***
AIRFLOW_CTX_DAG_ID=data_ingestion_fhv_dag
AIRFLOW_CTX_TASK_ID=bq_create_fhv_partitioned_clustered_table_task
AIRFLOW_CTX_EXECUTION_DATE=2019-02-01T00:00:00+00:00
AIRFLOW_CTX_DAG_RUN_ID=scheduled__2019-02-01T00:00:00+00:00
[2023-01-29 06:19:29,614] {crypto.py:82} WARNING - empty cryptography key - values will not be stored encrypted.
[2023-01-29 06:19:29,623] {logging_mixin.py:109} WARNING - /home/***/.local/lib/python3.7/site-packages/***/utils/context.py:152 AirflowContextDeprecationWarning: Accessing 'execution_date' from the template is deprecated and will be removed in a future version. Please use 'data_interval_start' or 'logical_date' instead.
[2023-01-29 06:19:29,634] {bigquery.py:1637} INFO - Inserting job ***_data_ingestion_fhv_dag_bq_create_fhv_partitioned_clustered_table_task_2019_02_01T00_00_00_00_00_c0c3505cdd35a9007930885cf1783383
[2023-01-29 06:19:33,072] {taskinstance.py:1700} ERROR - Task failed with exception
Traceback (most recent call last):
  File "/home/airflow/.local/lib/python3.7/site-packages/airflow/models/taskinstance.py", line 1329, in _run_raw_task
    self._execute_task_with_callbacks(context)
  File "/home/airflow/.local/lib/python3.7/site-packages/airflow/models/taskinstance.py", line 1455, in _execute_task_with_callbacks
    result = self._execute_task(context, self.task)
  File "/home/airflow/.local/lib/python3.7/site-packages/airflow/models/taskinstance.py", line 1511, in _execute_task
    result = execute_callable(context=context)
  File "/home/airflow/.local/lib/python3.7/site-packages/airflow/providers/google/cloud/operators/bigquery.py", line 2287, in execute
    job = self._submit_job(hook, job_id)
  File "/home/airflow/.local/lib/python3.7/site-packages/airflow/providers/google/cloud/operators/bigquery.py", line 2253, in _submit_job
    job_id=job_id,
  File "/home/airflow/.local/lib/python3.7/site-packages/airflow/providers/google/common/hooks/base_google.py", line 430, in inner_wrapper
    return func(self, *args, **kwargs)
  File "/home/airflow/.local/lib/python3.7/site-packages/airflow/providers/google/cloud/hooks/bigquery.py", line 1639, in insert_job
    job.result()
  File "/home/airflow/.local/lib/python3.7/site-packages/google/cloud/bigquery/job/query.py", line 1447, in result
    do_get_result()
  File "/home/airflow/.local/lib/python3.7/site-packages/google/cloud/bigquery/job/query.py", line 1437, in do_get_result
    super(QueryJob, self).result(retry=retry, timeout=timeout)
  File "/home/airflow/.local/lib/python3.7/site-packages/google/cloud/bigquery/job/base.py", line 727, in result
    return super(_AsyncJob, self).result(timeout=timeout, **kwargs)
  File "/home/airflow/.local/lib/python3.7/site-packages/google/api_core/future/polling.py", line 135, in result
    raise self._exception
google.api_core.exceptions.BadRequest: 400 Error while reading table: trips_data_all.fhv_external_table, error message: Parquet column 'DOlocationID' has type INT64 which does not match the target cpp_type DOUBLE. File: gs://dtc_data_lake_ny-rides-kelvin/raw/fhv_tripdata_2019-05.parquet

(job ID: airflow_data_ingestion_fhv_dag_bq_create_fhv_partitioned_clustered_table_task_2019_02_01T00_00_00_00_00_c0c3505cdd35a9007930885cf1783383)

                                                                                        -----Query Job SQL Follows-----                                                                                         

    |    .    |    .    |    .    |    .    |    .    |    .    |    .    |    .    |    .    |    .    |    .    |    .    |    .    |    .    |    .    |    .    |    .    |    .    |    .    |    .    |
   1:CREATE OR REPLACE TABLE trips_data_all.fhv_tripdata         PARTITION BY DATE(dropOff_datetime)         CLUSTER BY dispatching_base_num         AS         SELECT * FROM trips_data_all.fhv_external_table;
    |    .    |    .    |    .    |    .    |    .    |    .    |    .    |    .    |    .    |    .    |    .    |    .    |    .    |    .    |    .    |    .    |    .    |    .    |    .    |    .    |
[2023-01-29 06:19:33,100] {taskinstance.py:1277} INFO - Marking task as UP_FOR_RETRY. dag_id=data_ingestion_fhv_dag, task_id=bq_create_fhv_partitioned_clustered_table_task, execution_date=20190201T000000, start_date=20230129T061929, end_date=20230129T061933
[2023-01-29 06:19:33,115] {standard_task_runner.py:92} ERROR - Failed to execute job 248 for task bq_create_fhv_partitioned_clustered_table_task
Traceback (most recent call last):
  File "/home/airflow/.local/lib/python3.7/site-packages/airflow/task/task_runner/standard_task_runner.py", line 85, in _start_by_fork
    args.func(args, dag=self.dag)
  File "/home/airflow/.local/lib/python3.7/site-packages/airflow/cli/cli_parser.py", line 48, in command
    return func(*args, **kwargs)
  File "/home/airflow/.local/lib/python3.7/site-packages/airflow/utils/cli.py", line 92, in wrapper
    return f(*args, **kwargs)
  File "/home/airflow/.local/lib/python3.7/site-packages/airflow/cli/commands/task_command.py", line 298, in task_run
    _run_task_by_selected_method(args, dag, ti)
  File "/home/airflow/.local/lib/python3.7/site-packages/airflow/cli/commands/task_command.py", line 107, in _run_task_by_selected_method
    _run_raw_task(args, ti)
  File "/home/airflow/.local/lib/python3.7/site-packages/airflow/cli/commands/task_command.py", line 184, in _run_raw_task
    error_file=args.error_file,
  File "/home/airflow/.local/lib/python3.7/site-packages/airflow/utils/session.py", line 70, in wrapper
    return func(*args, session=session, **kwargs)
  File "/home/airflow/.local/lib/python3.7/site-packages/airflow/models/taskinstance.py", line 1329, in _run_raw_task
    self._execute_task_with_callbacks(context)
  File "/home/airflow/.local/lib/python3.7/site-packages/airflow/models/taskinstance.py", line 1455, in _execute_task_with_callbacks
    result = self._execute_task(context, self.task)
  File "/home/airflow/.local/lib/python3.7/site-packages/airflow/models/taskinstance.py", line 1511, in _execute_task
    result = execute_callable(context=context)
  File "/home/airflow/.local/lib/python3.7/site-packages/airflow/providers/google/cloud/operators/bigquery.py", line 2287, in execute
    job = self._submit_job(hook, job_id)
  File "/home/airflow/.local/lib/python3.7/site-packages/airflow/providers/google/cloud/operators/bigquery.py", line 2253, in _submit_job
    job_id=job_id,
  File "/home/airflow/.local/lib/python3.7/site-packages/airflow/providers/google/common/hooks/base_google.py", line 430, in inner_wrapper
    return func(self, *args, **kwargs)
  File "/home/airflow/.local/lib/python3.7/site-packages/airflow/providers/google/cloud/hooks/bigquery.py", line 1639, in insert_job
    job.result()
  File "/home/airflow/.local/lib/python3.7/site-packages/google/cloud/bigquery/job/query.py", line 1447, in result
    do_get_result()
  File "/home/airflow/.local/lib/python3.7/site-packages/google/cloud/bigquery/job/query.py", line 1437, in do_get_result
    super(QueryJob, self).result(retry=retry, timeout=timeout)
  File "/home/airflow/.local/lib/python3.7/site-packages/google/cloud/bigquery/job/base.py", line 727, in result
    return super(_AsyncJob, self).result(timeout=timeout, **kwargs)
  File "/home/airflow/.local/lib/python3.7/site-packages/google/api_core/future/polling.py", line 135, in result
    raise self._exception
google.api_core.exceptions.BadRequest: 400 Error while reading table: trips_data_all.fhv_external_table, error message: Parquet column 'DOlocationID' has type INT64 which does not match the target cpp_type DOUBLE. File: gs://dtc_data_lake_ny-rides-kelvin/raw/fhv_tripdata_2019-05.parquet

(job ID: airflow_data_ingestion_fhv_dag_bq_create_fhv_partitioned_clustered_table_task_2019_02_01T00_00_00_00_00_c0c3505cdd35a9007930885cf1783383)

                                                                                        -----Query Job SQL Follows-----                                                                                         

    |    .    |    .    |    .    |    .    |    .    |    .    |    .    |    .    |    .    |    .    |    .    |    .    |    .    |    .    |    .    |    .    |    .    |    .    |    .    |    .    |
   1:CREATE OR REPLACE TABLE trips_data_all.fhv_tripdata         PARTITION BY DATE(dropOff_datetime)         CLUSTER BY dispatching_base_num         AS         SELECT * FROM trips_data_all.fhv_external_table;
    |    .    |    .    |    .    |    .    |    .    |    .    |    .    |    .    |    .    |    .    |    .    |    .    |    .    |    .    |    .    |    .    |    .    |    .    |    .    |    .    |
[2023-01-29 06:19:33,162] {local_task_job.py:154} INFO - Task exited with return code 1
[2023-01-29 06:19:33,196] {local_task_job.py:264} INFO - 0 downstream tasks scheduled from follow-on schedule check
[2023-01-29 13:24:08,324] {taskinstance.py:1032} INFO - Dependencies all met for <TaskInstance: data_ingestion_fhv_dag.bq_create_fhv_partitioned_clustered_table_task scheduled__2019-02-01T00:00:00+00:00 [queued]>
[2023-01-29 13:24:08,340] {taskinstance.py:1032} INFO - Dependencies all met for <TaskInstance: data_ingestion_fhv_dag.bq_create_fhv_partitioned_clustered_table_task scheduled__2019-02-01T00:00:00+00:00 [queued]>
[2023-01-29 13:24:08,341] {taskinstance.py:1238} INFO - 
--------------------------------------------------------------------------------
[2023-01-29 13:24:08,342] {taskinstance.py:1239} INFO - Starting attempt 1 of 2
[2023-01-29 13:24:08,343] {taskinstance.py:1240} INFO - 
--------------------------------------------------------------------------------
[2023-01-29 13:24:08,363] {taskinstance.py:1259} INFO - Executing <Task(BigQueryInsertJobOperator): bq_create_fhv_partitioned_clustered_table_task> on 2019-02-01 00:00:00+00:00
[2023-01-29 13:24:08,370] {standard_task_runner.py:52} INFO - Started process 1514 to run task
[2023-01-29 13:24:08,377] {standard_task_runner.py:76} INFO - Running: ['***', 'tasks', 'run', 'data_ingestion_fhv_dag', 'bq_create_fhv_partitioned_clustered_table_task', 'scheduled__2019-02-01T00:00:00+00:00', '--job-id', '498', '--raw', '--subdir', 'DAGS_FOLDER/data_ingestion_fhv_dag.py', '--cfg-path', '/tmp/tmp9qhp8qwz', '--error-file', '/tmp/tmp5rt7qc1t']
[2023-01-29 13:24:08,378] {standard_task_runner.py:77} INFO - Job 498: Subtask bq_create_fhv_partitioned_clustered_table_task
[2023-01-29 13:24:08,443] {logging_mixin.py:109} INFO - Running <TaskInstance: data_ingestion_fhv_dag.bq_create_fhv_partitioned_clustered_table_task scheduled__2019-02-01T00:00:00+00:00 [running]> on host 2530f37057aa
[2023-01-29 13:24:08,521] {taskinstance.py:1426} INFO - Exporting the following env vars:
AIRFLOW_CTX_DAG_OWNER=***
AIRFLOW_CTX_DAG_ID=data_ingestion_fhv_dag
AIRFLOW_CTX_TASK_ID=bq_create_fhv_partitioned_clustered_table_task
AIRFLOW_CTX_EXECUTION_DATE=2019-02-01T00:00:00+00:00
AIRFLOW_CTX_DAG_RUN_ID=scheduled__2019-02-01T00:00:00+00:00
[2023-01-29 13:24:08,523] {crypto.py:82} WARNING - empty cryptography key - values will not be stored encrypted.
[2023-01-29 13:24:08,531] {logging_mixin.py:109} WARNING - /home/***/.local/lib/python3.7/site-packages/***/utils/context.py:152 AirflowContextDeprecationWarning: Accessing 'execution_date' from the template is deprecated and will be removed in a future version. Please use 'data_interval_start' or 'logical_date' instead.
[2023-01-29 13:24:08,539] {bigquery.py:1637} INFO - Inserting job ***_data_ingestion_fhv_dag_bq_create_fhv_partitioned_clustered_table_task_2019_02_01T00_00_00_00_00_a1509f06197ddfadd22f4a0e197a7561
[2023-01-29 13:24:11,133] {taskinstance.py:1700} ERROR - Task failed with exception
Traceback (most recent call last):
  File "/home/airflow/.local/lib/python3.7/site-packages/airflow/models/taskinstance.py", line 1329, in _run_raw_task
    self._execute_task_with_callbacks(context)
  File "/home/airflow/.local/lib/python3.7/site-packages/airflow/models/taskinstance.py", line 1455, in _execute_task_with_callbacks
    result = self._execute_task(context, self.task)
  File "/home/airflow/.local/lib/python3.7/site-packages/airflow/models/taskinstance.py", line 1511, in _execute_task
    result = execute_callable(context=context)
  File "/home/airflow/.local/lib/python3.7/site-packages/airflow/providers/google/cloud/operators/bigquery.py", line 2287, in execute
    job = self._submit_job(hook, job_id)
  File "/home/airflow/.local/lib/python3.7/site-packages/airflow/providers/google/cloud/operators/bigquery.py", line 2253, in _submit_job
    job_id=job_id,
  File "/home/airflow/.local/lib/python3.7/site-packages/airflow/providers/google/common/hooks/base_google.py", line 430, in inner_wrapper
    return func(self, *args, **kwargs)
  File "/home/airflow/.local/lib/python3.7/site-packages/airflow/providers/google/cloud/hooks/bigquery.py", line 1639, in insert_job
    job.result()
  File "/home/airflow/.local/lib/python3.7/site-packages/google/cloud/bigquery/job/query.py", line 1447, in result
    do_get_result()
  File "/home/airflow/.local/lib/python3.7/site-packages/google/cloud/bigquery/job/query.py", line 1437, in do_get_result
    super(QueryJob, self).result(retry=retry, timeout=timeout)
  File "/home/airflow/.local/lib/python3.7/site-packages/google/cloud/bigquery/job/base.py", line 727, in result
    return super(_AsyncJob, self).result(timeout=timeout, **kwargs)
  File "/home/airflow/.local/lib/python3.7/site-packages/google/api_core/future/polling.py", line 135, in result
    raise self._exception
google.api_core.exceptions.BadRequest: 400 Unrecognized name: dropOff_datetime at [1:91]

(job ID: airflow_data_ingestion_fhv_dag_bq_create_fhv_partitioned_clustered_table_task_2019_02_01T00_00_00_00_00_a1509f06197ddfadd22f4a0e197a7561)

                                                                                               -----Query Job SQL Follows-----                                                                                                

    |    .    |    .    |    .    |    .    |    .    |    .    |    .    |    .    |    .    |    .    |    .    |    .    |    .    |    .    |    .    |    .    |    .    |    .    |    .    |    .    |    .    |
   1:CREATE OR REPLACE TABLE trips_data_all.fhv_tripdata_partitioned         PARTITION BY DATE(dropOff_datetime)         CLUSTER BY dispatching_base_num         AS         (SELECT * FROM trips_data_all.fhv_external_table);
    |    .    |    .    |    .    |    .    |    .    |    .    |    .    |    .    |    .    |    .    |    .    |    .    |    .    |    .    |    .    |    .    |    .    |    .    |    .    |    .    |    .    |
[2023-01-29 13:24:11,151] {taskinstance.py:1277} INFO - Marking task as UP_FOR_RETRY. dag_id=data_ingestion_fhv_dag, task_id=bq_create_fhv_partitioned_clustered_table_task, execution_date=20190201T000000, start_date=20230129T132408, end_date=20230129T132411
[2023-01-29 13:24:11,165] {standard_task_runner.py:92} ERROR - Failed to execute job 498 for task bq_create_fhv_partitioned_clustered_table_task
Traceback (most recent call last):
  File "/home/airflow/.local/lib/python3.7/site-packages/airflow/task/task_runner/standard_task_runner.py", line 85, in _start_by_fork
    args.func(args, dag=self.dag)
  File "/home/airflow/.local/lib/python3.7/site-packages/airflow/cli/cli_parser.py", line 48, in command
    return func(*args, **kwargs)
  File "/home/airflow/.local/lib/python3.7/site-packages/airflow/utils/cli.py", line 92, in wrapper
    return f(*args, **kwargs)
  File "/home/airflow/.local/lib/python3.7/site-packages/airflow/cli/commands/task_command.py", line 298, in task_run
    _run_task_by_selected_method(args, dag, ti)
  File "/home/airflow/.local/lib/python3.7/site-packages/airflow/cli/commands/task_command.py", line 107, in _run_task_by_selected_method
    _run_raw_task(args, ti)
  File "/home/airflow/.local/lib/python3.7/site-packages/airflow/cli/commands/task_command.py", line 184, in _run_raw_task
    error_file=args.error_file,
  File "/home/airflow/.local/lib/python3.7/site-packages/airflow/utils/session.py", line 70, in wrapper
    return func(*args, session=session, **kwargs)
  File "/home/airflow/.local/lib/python3.7/site-packages/airflow/models/taskinstance.py", line 1329, in _run_raw_task
    self._execute_task_with_callbacks(context)
  File "/home/airflow/.local/lib/python3.7/site-packages/airflow/models/taskinstance.py", line 1455, in _execute_task_with_callbacks
    result = self._execute_task(context, self.task)
  File "/home/airflow/.local/lib/python3.7/site-packages/airflow/models/taskinstance.py", line 1511, in _execute_task
    result = execute_callable(context=context)
  File "/home/airflow/.local/lib/python3.7/site-packages/airflow/providers/google/cloud/operators/bigquery.py", line 2287, in execute
    job = self._submit_job(hook, job_id)
  File "/home/airflow/.local/lib/python3.7/site-packages/airflow/providers/google/cloud/operators/bigquery.py", line 2253, in _submit_job
    job_id=job_id,
  File "/home/airflow/.local/lib/python3.7/site-packages/airflow/providers/google/common/hooks/base_google.py", line 430, in inner_wrapper
    return func(self, *args, **kwargs)
  File "/home/airflow/.local/lib/python3.7/site-packages/airflow/providers/google/cloud/hooks/bigquery.py", line 1639, in insert_job
    job.result()
  File "/home/airflow/.local/lib/python3.7/site-packages/google/cloud/bigquery/job/query.py", line 1447, in result
    do_get_result()
  File "/home/airflow/.local/lib/python3.7/site-packages/google/cloud/bigquery/job/query.py", line 1437, in do_get_result
    super(QueryJob, self).result(retry=retry, timeout=timeout)
  File "/home/airflow/.local/lib/python3.7/site-packages/google/cloud/bigquery/job/base.py", line 727, in result
    return super(_AsyncJob, self).result(timeout=timeout, **kwargs)
  File "/home/airflow/.local/lib/python3.7/site-packages/google/api_core/future/polling.py", line 135, in result
    raise self._exception
google.api_core.exceptions.BadRequest: 400 Unrecognized name: dropOff_datetime at [1:91]

(job ID: airflow_data_ingestion_fhv_dag_bq_create_fhv_partitioned_clustered_table_task_2019_02_01T00_00_00_00_00_a1509f06197ddfadd22f4a0e197a7561)

                                                                                               -----Query Job SQL Follows-----                                                                                                

    |    .    |    .    |    .    |    .    |    .    |    .    |    .    |    .    |    .    |    .    |    .    |    .    |    .    |    .    |    .    |    .    |    .    |    .    |    .    |    .    |    .    |
   1:CREATE OR REPLACE TABLE trips_data_all.fhv_tripdata_partitioned         PARTITION BY DATE(dropOff_datetime)         CLUSTER BY dispatching_base_num         AS         (SELECT * FROM trips_data_all.fhv_external_table);
    |    .    |    .    |    .    |    .    |    .    |    .    |    .    |    .    |    .    |    .    |    .    |    .    |    .    |    .    |    .    |    .    |    .    |    .    |    .    |    .    |    .    |
[2023-01-29 13:24:11,181] {local_task_job.py:154} INFO - Task exited with return code 1
[2023-01-29 13:24:11,210] {local_task_job.py:264} INFO - 0 downstream tasks scheduled from follow-on schedule check
