[2023-01-29 12:14:39,311] {taskinstance.py:1032} INFO - Dependencies all met for <TaskInstance: data_ingestion_gcs_dag.modify_parquet_column_type_task scheduled__2019-01-01T00:00:00+00:00 [queued]>
[2023-01-29 12:14:39,323] {taskinstance.py:1032} INFO - Dependencies all met for <TaskInstance: data_ingestion_gcs_dag.modify_parquet_column_type_task scheduled__2019-01-01T00:00:00+00:00 [queued]>
[2023-01-29 12:14:39,324] {taskinstance.py:1238} INFO - 
--------------------------------------------------------------------------------
[2023-01-29 12:14:39,326] {taskinstance.py:1239} INFO - Starting attempt 1 of 2
[2023-01-29 12:14:39,328] {taskinstance.py:1240} INFO - 
--------------------------------------------------------------------------------
[2023-01-29 12:14:39,343] {taskinstance.py:1259} INFO - Executing <Task(PythonOperator): modify_parquet_column_type_task> on 2019-01-01 00:00:00+00:00
[2023-01-29 12:14:39,350] {standard_task_runner.py:52} INFO - Started process 2481 to run task
[2023-01-29 12:14:39,354] {standard_task_runner.py:76} INFO - Running: ['***', 'tasks', 'run', 'data_ingestion_gcs_dag', 'modify_parquet_column_type_task', 'scheduled__2019-01-01T00:00:00+00:00', '--job-id', '355', '--raw', '--subdir', 'DAGS_FOLDER/data_ingestion_gcs_dag.py', '--cfg-path', '/tmp/tmp8h1r_xao', '--error-file', '/tmp/tmpje_ltfr8']
[2023-01-29 12:14:39,355] {standard_task_runner.py:77} INFO - Job 355: Subtask modify_parquet_column_type_task
[2023-01-29 12:14:39,439] {logging_mixin.py:109} INFO - Running <TaskInstance: data_ingestion_gcs_dag.modify_parquet_column_type_task scheduled__2019-01-01T00:00:00+00:00 [running]> on host 2530f37057aa
[2023-01-29 12:14:39,499] {logging_mixin.py:109} WARNING - /home/***/.local/lib/python3.7/site-packages/***/utils/context.py:152 AirflowContextDeprecationWarning: Accessing 'execution_date' from the template is deprecated and will be removed in a future version. Please use 'data_interval_start' or 'logical_date' instead.
[2023-01-29 12:14:39,538] {taskinstance.py:1426} INFO - Exporting the following env vars:
AIRFLOW_CTX_DAG_OWNER=***
AIRFLOW_CTX_DAG_ID=data_ingestion_gcs_dag
AIRFLOW_CTX_TASK_ID=modify_parquet_column_type_task
AIRFLOW_CTX_EXECUTION_DATE=2019-01-01T00:00:00+00:00
AIRFLOW_CTX_DAG_RUN_ID=scheduled__2019-01-01T00:00:00+00:00
[2023-01-29 12:14:39,540] {logging_mixin.py:109} INFO - bucket dtc_data_lake_ny-rides-kelvin
[2023-01-29 12:14:39,541] {logging_mixin.py:109} INFO - file_path raw/fhv_tripdata_2019-01.parquet
[2023-01-29 12:14:39,542] {logging_mixin.py:109} INFO - column_name DOlocationID
[2023-01-29 12:14:39,545] {taskinstance.py:1700} ERROR - Task failed with exception
Traceback (most recent call last):
  File "/home/airflow/.local/lib/python3.7/site-packages/airflow/models/taskinstance.py", line 1329, in _run_raw_task
    self._execute_task_with_callbacks(context)
  File "/home/airflow/.local/lib/python3.7/site-packages/airflow/models/taskinstance.py", line 1455, in _execute_task_with_callbacks
    result = self._execute_task(context, self.task)
  File "/home/airflow/.local/lib/python3.7/site-packages/airflow/models/taskinstance.py", line 1511, in _execute_task
    result = execute_callable(context=context)
  File "/home/airflow/.local/lib/python3.7/site-packages/airflow/operators/python.py", line 174, in execute
    return_value = self.execute_callable()
  File "/home/airflow/.local/lib/python3.7/site-packages/airflow/operators/python.py", line 185, in execute_callable
    return self.python_callable(*self.op_args, **self.op_kwargs)
  File "/opt/airflow/dags/data_ingestion_gcs_dag.py", line 74, in modify_parquet_column_type
    table = pq.ParquetFile(gcs_path).read()
  File "/home/airflow/.local/lib/python3.7/site-packages/pyarrow/parquet.py", line 232, in __init__
    coerce_int96_timestamp_unit=coerce_int96_timestamp_unit
  File "pyarrow/_parquet.pyx", line 966, in pyarrow._parquet.ParquetReader.open
  File "pyarrow/io.pxi", line 1531, in pyarrow.lib.get_reader
  File "pyarrow/io.pxi", line 1522, in pyarrow.lib.get_native_file
  File "pyarrow/io.pxi", line 886, in pyarrow.lib.OSFile.__cinit__
  File "pyarrow/io.pxi", line 896, in pyarrow.lib.OSFile._open_readable
  File "pyarrow/error.pxi", line 143, in pyarrow.lib.pyarrow_internal_check_status
  File "pyarrow/error.pxi", line 112, in pyarrow.lib.check_status
FileNotFoundError: [Errno 2] Failed to open local file 'gs://dtc_data_lake_ny-rides-kelvin/raw/fhv_tripdata_2019-01.parquet'. Detail: [errno 2] No such file or directory
[2023-01-29 12:14:39,563] {taskinstance.py:1277} INFO - Marking task as UP_FOR_RETRY. dag_id=data_ingestion_gcs_dag, task_id=modify_parquet_column_type_task, execution_date=20190101T000000, start_date=20230129T121439, end_date=20230129T121439
[2023-01-29 12:14:39,586] {standard_task_runner.py:92} ERROR - Failed to execute job 355 for task modify_parquet_column_type_task
Traceback (most recent call last):
  File "/home/airflow/.local/lib/python3.7/site-packages/airflow/task/task_runner/standard_task_runner.py", line 85, in _start_by_fork
    args.func(args, dag=self.dag)
  File "/home/airflow/.local/lib/python3.7/site-packages/airflow/cli/cli_parser.py", line 48, in command
    return func(*args, **kwargs)
  File "/home/airflow/.local/lib/python3.7/site-packages/airflow/utils/cli.py", line 92, in wrapper
    return f(*args, **kwargs)
  File "/home/airflow/.local/lib/python3.7/site-packages/airflow/cli/commands/task_command.py", line 298, in task_run
    _run_task_by_selected_method(args, dag, ti)
  File "/home/airflow/.local/lib/python3.7/site-packages/airflow/cli/commands/task_command.py", line 107, in _run_task_by_selected_method
    _run_raw_task(args, ti)
  File "/home/airflow/.local/lib/python3.7/site-packages/airflow/cli/commands/task_command.py", line 184, in _run_raw_task
    error_file=args.error_file,
  File "/home/airflow/.local/lib/python3.7/site-packages/airflow/utils/session.py", line 70, in wrapper
    return func(*args, session=session, **kwargs)
  File "/home/airflow/.local/lib/python3.7/site-packages/airflow/models/taskinstance.py", line 1329, in _run_raw_task
    self._execute_task_with_callbacks(context)
  File "/home/airflow/.local/lib/python3.7/site-packages/airflow/models/taskinstance.py", line 1455, in _execute_task_with_callbacks
    result = self._execute_task(context, self.task)
  File "/home/airflow/.local/lib/python3.7/site-packages/airflow/models/taskinstance.py", line 1511, in _execute_task
    result = execute_callable(context=context)
  File "/home/airflow/.local/lib/python3.7/site-packages/airflow/operators/python.py", line 174, in execute
    return_value = self.execute_callable()
  File "/home/airflow/.local/lib/python3.7/site-packages/airflow/operators/python.py", line 185, in execute_callable
    return self.python_callable(*self.op_args, **self.op_kwargs)
  File "/opt/airflow/dags/data_ingestion_gcs_dag.py", line 74, in modify_parquet_column_type
    table = pq.ParquetFile(gcs_path).read()
  File "/home/airflow/.local/lib/python3.7/site-packages/pyarrow/parquet.py", line 232, in __init__
    coerce_int96_timestamp_unit=coerce_int96_timestamp_unit
  File "pyarrow/_parquet.pyx", line 966, in pyarrow._parquet.ParquetReader.open
  File "pyarrow/io.pxi", line 1531, in pyarrow.lib.get_reader
  File "pyarrow/io.pxi", line 1522, in pyarrow.lib.get_native_file
  File "pyarrow/io.pxi", line 886, in pyarrow.lib.OSFile.__cinit__
  File "pyarrow/io.pxi", line 896, in pyarrow.lib.OSFile._open_readable
  File "pyarrow/error.pxi", line 143, in pyarrow.lib.pyarrow_internal_check_status
  File "pyarrow/error.pxi", line 112, in pyarrow.lib.check_status
FileNotFoundError: [Errno 2] Failed to open local file 'gs://dtc_data_lake_ny-rides-kelvin/raw/fhv_tripdata_2019-01.parquet'. Detail: [errno 2] No such file or directory
[2023-01-29 12:14:39,611] {local_task_job.py:154} INFO - Task exited with return code 1
[2023-01-29 12:14:39,656] {local_task_job.py:264} INFO - 0 downstream tasks scheduled from follow-on schedule check
