[2023-01-29 12:41:14,806] {taskinstance.py:1032} INFO - Dependencies all met for <TaskInstance: data_ingestion_gcs_dag.cast_parquet_columns_task scheduled__2019-03-01T00:00:00+00:00 [queued]>
[2023-01-29 12:41:14,825] {taskinstance.py:1032} INFO - Dependencies all met for <TaskInstance: data_ingestion_gcs_dag.cast_parquet_columns_task scheduled__2019-03-01T00:00:00+00:00 [queued]>
[2023-01-29 12:41:14,826] {taskinstance.py:1238} INFO - 
--------------------------------------------------------------------------------
[2023-01-29 12:41:14,828] {taskinstance.py:1239} INFO - Starting attempt 1 of 2
[2023-01-29 12:41:14,829] {taskinstance.py:1240} INFO - 
--------------------------------------------------------------------------------
[2023-01-29 12:41:14,847] {taskinstance.py:1259} INFO - Executing <Task(PythonOperator): cast_parquet_columns_task> on 2019-03-01 00:00:00+00:00
[2023-01-29 12:41:14,854] {standard_task_runner.py:52} INFO - Started process 6454 to run task
[2023-01-29 12:41:14,859] {standard_task_runner.py:76} INFO - Running: ['***', 'tasks', 'run', 'data_ingestion_gcs_dag', 'cast_parquet_columns_task', 'scheduled__2019-03-01T00:00:00+00:00', '--job-id', '383', '--raw', '--subdir', 'DAGS_FOLDER/data_ingestion_gcs_dag.py', '--cfg-path', '/tmp/tmpper0e2ex', '--error-file', '/tmp/tmph186qmwy']
[2023-01-29 12:41:14,861] {standard_task_runner.py:77} INFO - Job 383: Subtask cast_parquet_columns_task
[2023-01-29 12:41:14,936] {logging_mixin.py:109} INFO - Running <TaskInstance: data_ingestion_gcs_dag.cast_parquet_columns_task scheduled__2019-03-01T00:00:00+00:00 [running]> on host 2530f37057aa
[2023-01-29 12:41:15,027] {logging_mixin.py:109} WARNING - /home/***/.local/lib/python3.7/site-packages/***/utils/context.py:152 AirflowContextDeprecationWarning: Accessing 'execution_date' from the template is deprecated and will be removed in a future version. Please use 'data_interval_start' or 'logical_date' instead.
[2023-01-29 12:41:15,055] {taskinstance.py:1426} INFO - Exporting the following env vars:
AIRFLOW_CTX_DAG_OWNER=***
AIRFLOW_CTX_DAG_ID=data_ingestion_gcs_dag
AIRFLOW_CTX_TASK_ID=cast_parquet_columns_task
AIRFLOW_CTX_EXECUTION_DATE=2019-03-01T00:00:00+00:00
AIRFLOW_CTX_DAG_RUN_ID=scheduled__2019-03-01T00:00:00+00:00
[2023-01-29 12:41:15,059] {logging_mixin.py:109} INFO - /opt/***
[2023-01-29 12:41:15,368] {logging_mixin.py:109} WARNING - --- Logging error ---
[2023-01-29 12:41:15,379] {logging_mixin.py:109} WARNING - Traceback (most recent call last):
[2023-01-29 12:41:15,382] {logging_mixin.py:109} WARNING -   File "/usr/local/lib/python3.7/logging/__init__.py", line 1025, in emit
    msg = self.format(record)
[2023-01-29 12:41:15,383] {logging_mixin.py:109} WARNING -   File "/usr/local/lib/python3.7/logging/__init__.py", line 869, in format
    return fmt.format(record)
[2023-01-29 12:41:15,385] {logging_mixin.py:109} WARNING -   File "/usr/local/lib/python3.7/logging/__init__.py", line 608, in format
    record.message = record.getMessage()
[2023-01-29 12:41:15,386] {logging_mixin.py:109} WARNING -   File "/usr/local/lib/python3.7/logging/__init__.py", line 369, in getMessage
    msg = msg % self.args
[2023-01-29 12:41:15,388] {logging_mixin.py:109} WARNING - TypeError: not all arguments converted during string formatting
[2023-01-29 12:41:15,390] {logging_mixin.py:109} WARNING - Call stack:
[2023-01-29 12:41:15,414] {logging_mixin.py:109} WARNING -   File "/home/***/.local/bin/***", line 8, in <module>
    sys.exit(main())
[2023-01-29 12:41:15,415] {logging_mixin.py:109} WARNING -   File "/home/***/.local/lib/python3.7/site-packages/***/__main__.py", line 48, in main
    args.func(args)
[2023-01-29 12:41:15,417] {logging_mixin.py:109} WARNING -   File "/home/***/.local/lib/python3.7/site-packages/***/cli/cli_parser.py", line 48, in command
    return func(*args, **kwargs)
[2023-01-29 12:41:15,418] {logging_mixin.py:109} WARNING -   File "/home/***/.local/lib/python3.7/site-packages/***/utils/cli.py", line 92, in wrapper
    return f(*args, **kwargs)
[2023-01-29 12:41:15,419] {logging_mixin.py:109} WARNING -   File "/home/***/.local/lib/python3.7/site-packages/***/cli/commands/scheduler_command.py", line 75, in scheduler
    _run_scheduler_job(args=args)
[2023-01-29 12:41:15,421] {logging_mixin.py:109} WARNING -   File "/home/***/.local/lib/python3.7/site-packages/***/cli/commands/scheduler_command.py", line 46, in _run_scheduler_job
    job.run()
[2023-01-29 12:41:15,423] {logging_mixin.py:109} WARNING -   File "/home/***/.local/lib/python3.7/site-packages/***/jobs/base_job.py", line 245, in run
    self._execute()
[2023-01-29 12:41:15,424] {logging_mixin.py:109} WARNING -   File "/home/***/.local/lib/python3.7/site-packages/***/jobs/scheduler_job.py", line 620, in _execute
    self.executor.start()
[2023-01-29 12:41:15,425] {logging_mixin.py:109} WARNING -   File "/home/***/.local/lib/python3.7/site-packages/***/executors/local_executor.py", line 356, in start
    self.impl.start()
[2023-01-29 12:41:15,426] {logging_mixin.py:109} WARNING -   File "/home/***/.local/lib/python3.7/site-packages/***/executors/local_executor.py", line 298, in start
    worker.start()
[2023-01-29 12:41:15,428] {logging_mixin.py:109} WARNING -   File "/usr/local/lib/python3.7/multiprocessing/process.py", line 112, in start
    self._popen = self._Popen(self)
[2023-01-29 12:41:15,429] {logging_mixin.py:109} WARNING -   File "/usr/local/lib/python3.7/multiprocessing/context.py", line 223, in _Popen
    return _default_context.get_context().Process._Popen(process_obj)
[2023-01-29 12:41:15,430] {logging_mixin.py:109} WARNING -   File "/usr/local/lib/python3.7/multiprocessing/context.py", line 277, in _Popen
    return Popen(process_obj)
[2023-01-29 12:41:15,431] {logging_mixin.py:109} WARNING -   File "/usr/local/lib/python3.7/multiprocessing/popen_fork.py", line 20, in __init__
    self._launch(process_obj)
[2023-01-29 12:41:15,431] {logging_mixin.py:109} WARNING -   File "/usr/local/lib/python3.7/multiprocessing/popen_fork.py", line 74, in _launch
    code = process_obj._bootstrap()
[2023-01-29 12:41:15,433] {logging_mixin.py:109} WARNING -   File "/usr/local/lib/python3.7/multiprocessing/process.py", line 297, in _bootstrap
    self.run()
[2023-01-29 12:41:15,434] {logging_mixin.py:109} WARNING -   File "/home/***/.local/lib/python3.7/site-packages/***/executors/local_executor.py", line 67, in run
    return super().run()
[2023-01-29 12:41:15,435] {logging_mixin.py:109} WARNING -   File "/usr/local/lib/python3.7/multiprocessing/process.py", line 99, in run
    self._target(*self._args, **self._kwargs)
[2023-01-29 12:41:15,436] {logging_mixin.py:109} WARNING -   File "/home/***/.local/lib/python3.7/site-packages/***/executors/local_executor.py", line 190, in do_work
    self.execute_work(key=key, command=command)
[2023-01-29 12:41:15,438] {logging_mixin.py:109} WARNING -   File "/home/***/.local/lib/python3.7/site-packages/***/executors/local_executor.py", line 84, in execute_work
    state = self._execute_work_in_fork(command)
[2023-01-29 12:41:15,439] {logging_mixin.py:109} WARNING -   File "/home/***/.local/lib/python3.7/site-packages/***/executors/local_executor.py", line 124, in _execute_work_in_fork
    args.func(args)
[2023-01-29 12:41:15,440] {logging_mixin.py:109} WARNING -   File "/home/***/.local/lib/python3.7/site-packages/***/cli/cli_parser.py", line 48, in command
    return func(*args, **kwargs)
[2023-01-29 12:41:15,442] {logging_mixin.py:109} WARNING -   File "/home/***/.local/lib/python3.7/site-packages/***/utils/cli.py", line 92, in wrapper
    return f(*args, **kwargs)
[2023-01-29 12:41:15,443] {logging_mixin.py:109} WARNING -   File "/home/***/.local/lib/python3.7/site-packages/***/cli/commands/task_command.py", line 298, in task_run
    _run_task_by_selected_method(args, dag, ti)
[2023-01-29 12:41:15,444] {logging_mixin.py:109} WARNING -   File "/home/***/.local/lib/python3.7/site-packages/***/cli/commands/task_command.py", line 105, in _run_task_by_selected_method
    _run_task_by_local_task_job(args, ti)
[2023-01-29 12:41:15,445] {logging_mixin.py:109} WARNING -   File "/home/***/.local/lib/python3.7/site-packages/***/cli/commands/task_command.py", line 163, in _run_task_by_local_task_job
    run_job.run()
[2023-01-29 12:41:15,447] {logging_mixin.py:109} WARNING -   File "/home/***/.local/lib/python3.7/site-packages/***/jobs/base_job.py", line 245, in run
    self._execute()
[2023-01-29 12:41:15,448] {logging_mixin.py:109} WARNING -   File "/home/***/.local/lib/python3.7/site-packages/***/jobs/local_task_job.py", line 103, in _execute
    self.task_runner.start()
[2023-01-29 12:41:15,450] {logging_mixin.py:109} WARNING -   File "/home/***/.local/lib/python3.7/site-packages/***/task/task_runner/standard_task_runner.py", line 41, in start
    self.process = self._start_by_fork()
[2023-01-29 12:41:15,451] {logging_mixin.py:109} WARNING -   File "/home/***/.local/lib/python3.7/site-packages/***/task/task_runner/standard_task_runner.py", line 85, in _start_by_fork
    args.func(args, dag=self.dag)
[2023-01-29 12:41:15,452] {logging_mixin.py:109} WARNING -   File "/home/***/.local/lib/python3.7/site-packages/***/cli/cli_parser.py", line 48, in command
    return func(*args, **kwargs)
[2023-01-29 12:41:15,453] {logging_mixin.py:109} WARNING -   File "/home/***/.local/lib/python3.7/site-packages/***/utils/cli.py", line 92, in wrapper
    return f(*args, **kwargs)
[2023-01-29 12:41:15,454] {logging_mixin.py:109} WARNING -   File "/home/***/.local/lib/python3.7/site-packages/***/cli/commands/task_command.py", line 298, in task_run
    _run_task_by_selected_method(args, dag, ti)
[2023-01-29 12:41:15,455] {logging_mixin.py:109} WARNING -   File "/home/***/.local/lib/python3.7/site-packages/***/cli/commands/task_command.py", line 107, in _run_task_by_selected_method
    _run_raw_task(args, ti)
[2023-01-29 12:41:15,456] {logging_mixin.py:109} WARNING -   File "/home/***/.local/lib/python3.7/site-packages/***/cli/commands/task_command.py", line 184, in _run_raw_task
    error_file=args.error_file,
[2023-01-29 12:41:15,457] {logging_mixin.py:109} WARNING -   File "/home/***/.local/lib/python3.7/site-packages/***/utils/session.py", line 70, in wrapper
    return func(*args, session=session, **kwargs)
[2023-01-29 12:41:15,458] {logging_mixin.py:109} WARNING -   File "/home/***/.local/lib/python3.7/site-packages/***/models/taskinstance.py", line 1329, in _run_raw_task
    self._execute_task_with_callbacks(context)
[2023-01-29 12:41:15,459] {logging_mixin.py:109} WARNING -   File "/home/***/.local/lib/python3.7/site-packages/***/models/taskinstance.py", line 1455, in _execute_task_with_callbacks
    result = self._execute_task(context, self.task)
[2023-01-29 12:41:15,460] {logging_mixin.py:109} WARNING -   File "/home/***/.local/lib/python3.7/site-packages/***/models/taskinstance.py", line 1511, in _execute_task
    result = execute_callable(context=context)
[2023-01-29 12:41:15,461] {logging_mixin.py:109} WARNING -   File "/home/***/.local/lib/python3.7/site-packages/***/operators/python.py", line 174, in execute
    return_value = self.execute_callable()
[2023-01-29 12:41:15,462] {logging_mixin.py:109} WARNING -   File "/home/***/.local/lib/python3.7/site-packages/***/operators/python.py", line 185, in execute_callable
    return self.python_callable(*self.op_args, **self.op_kwargs)
[2023-01-29 12:41:15,464] {logging_mixin.py:109} WARNING -   File "/opt/***/dags/data_ingestion_gcs_dag.py", line 65, in cast_parquet_columns
    logging.info('table', table)
[2023-01-29 12:41:15,465] {logging_mixin.py:109} WARNING -   File "/usr/local/lib/python3.7/logging/__init__.py", line 1992, in info
    root.info(msg, *args, **kwargs)
[2023-01-29 12:41:15,466] {logging_mixin.py:109} WARNING -   File "/usr/local/lib/python3.7/logging/__init__.py", line 1378, in info
    self._log(INFO, msg, args, **kwargs)
[2023-01-29 12:41:15,468] {logging_mixin.py:109} WARNING -   File "/usr/local/lib/python3.7/logging/__init__.py", line 1514, in _log
    self.handle(record)
[2023-01-29 12:41:15,469] {logging_mixin.py:109} WARNING -   File "/usr/local/lib/python3.7/logging/__init__.py", line 1524, in handle
    self.callHandlers(record)
[2023-01-29 12:41:15,470] {logging_mixin.py:109} WARNING -   File "/usr/local/lib/python3.7/logging/__init__.py", line 1586, in callHandlers
    hdlr.handle(record)
[2023-01-29 12:41:15,473] {logging_mixin.py:109} WARNING -   File "/usr/local/lib/python3.7/logging/__init__.py", line 894, in handle
    self.emit(record)
[2023-01-29 12:41:15,475] {logging_mixin.py:109} WARNING -   File "/home/***/.local/lib/python3.7/site-packages/***/utils/log/file_task_handler.py", line 67, in emit
    self.handler.emit(record)
[2023-01-29 12:41:15,477] {logging_mixin.py:109} WARNING - Message: 'table'
Arguments: (pyarrow.Table
dispatching_base_num: string
pickup_datetime: timestamp[s]
dropOff_datetime: timestamp[s]
PUlocationID: int64
DOlocationID: int64
SR_Flag: int64
Affiliated_base_number: string,)
[2023-01-29 12:41:16,036] {python.py:175} INFO - Done. Returned value was: None
[2023-01-29 12:41:16,072] {taskinstance.py:1277} INFO - Marking task as SUCCESS. dag_id=data_ingestion_gcs_dag, task_id=cast_parquet_columns_task, execution_date=20190301T000000, start_date=20230129T124114, end_date=20230129T124116
[2023-01-29 12:41:16,167] {local_task_job.py:154} INFO - Task exited with return code 0
[2023-01-29 12:41:16,216] {local_task_job.py:264} INFO - 1 downstream tasks scheduled from follow-on schedule check
[2023-01-29 12:57:56,825] {taskinstance.py:1026} INFO - Dependencies not met for <TaskInstance: data_ingestion_gcs_dag.cast_parquet_columns_task scheduled__2019-03-01T00:00:00+00:00 [queued]>, dependency 'Execution Date' FAILED: The execution date is 2019-03-01T00:00:00+00:00 but this is after the task's end date 2019-01-01T00:00:00+00:00.
[2023-01-29 12:57:56,859] {local_task_job.py:99} INFO - Task is not able to be run
