[2023-01-28 03:33:20,027] {taskinstance.py:1032} INFO - Dependencies all met for <TaskInstance: data_ingestion_fhv_dag.download_dataset_task scheduled__2019-01-01T00:00:00+00:00 [queued]>
[2023-01-28 03:33:20,036] {taskinstance.py:1032} INFO - Dependencies all met for <TaskInstance: data_ingestion_fhv_dag.download_dataset_task scheduled__2019-01-01T00:00:00+00:00 [queued]>
[2023-01-28 03:33:20,037] {taskinstance.py:1238} INFO - 
--------------------------------------------------------------------------------
[2023-01-28 03:33:20,038] {taskinstance.py:1239} INFO - Starting attempt 2 of 3
[2023-01-28 03:33:20,038] {taskinstance.py:1240} INFO - 
--------------------------------------------------------------------------------
[2023-01-28 03:33:20,050] {taskinstance.py:1259} INFO - Executing <Task(BashOperator): download_dataset_task> on 2019-01-01 00:00:00+00:00
[2023-01-28 03:33:20,055] {standard_task_runner.py:52} INFO - Started process 18926 to run task
[2023-01-28 03:33:20,059] {standard_task_runner.py:76} INFO - Running: ['***', 'tasks', 'run', 'data_ingestion_fhv_dag', 'download_dataset_task', 'scheduled__2019-01-01T00:00:00+00:00', '--job-id', '110', '--raw', '--subdir', 'DAGS_FOLDER/data_ingestion_fhv_dag.py', '--cfg-path', '/tmp/tmp085ceuva', '--error-file', '/tmp/tmpd32pewdj']
[2023-01-28 03:33:20,060] {standard_task_runner.py:77} INFO - Job 110: Subtask download_dataset_task
[2023-01-28 03:33:20,125] {logging_mixin.py:109} INFO - Running <TaskInstance: data_ingestion_fhv_dag.download_dataset_task scheduled__2019-01-01T00:00:00+00:00 [running]> on host adbf820de9e6
[2023-01-28 03:33:20,172] {logging_mixin.py:109} WARNING - /home/***/.local/lib/python3.7/site-packages/***/utils/context.py:152 AirflowContextDeprecationWarning: Accessing 'execution_date' from the template is deprecated and will be removed in a future version. Please use 'data_interval_start' or 'logical_date' instead.
[2023-01-28 03:33:20,190] {taskinstance.py:1426} INFO - Exporting the following env vars:
AIRFLOW_CTX_DAG_OWNER=***
AIRFLOW_CTX_DAG_ID=data_ingestion_fhv_dag
AIRFLOW_CTX_TASK_ID=download_dataset_task
AIRFLOW_CTX_EXECUTION_DATE=2019-01-01T00:00:00+00:00
AIRFLOW_CTX_DAG_RUN_ID=scheduled__2019-01-01T00:00:00+00:00
[2023-01-28 03:33:20,193] {subprocess.py:62} INFO - Tmp dir root location: 
 /tmp
[2023-01-28 03:33:20,195] {subprocess.py:74} INFO - Running command: ['bash', '-c', 'curl -sSLf https://d37ci6vzurychx.cloudfront.net/trip-data/fhv_tripdata_2019-01.parquet > /opt/***/fhv_tripdata_2019-01.parquet']
[2023-01-28 03:33:20,210] {subprocess.py:85} INFO - Output:
[2023-01-28 03:33:35,211] {local_task_job.py:212} WARNING - State of this instance has been externally set to None. Terminating instance.
[2023-01-28 03:33:35,218] {process_utils.py:124} INFO - Sending Signals.SIGTERM to group 18926. PIDs of all processes in the group: [18927, 18928, 18926]
[2023-01-28 03:33:35,219] {process_utils.py:75} INFO - Sending the signal Signals.SIGTERM to group 18926
[2023-01-28 03:33:35,221] {taskinstance.py:1408} ERROR - Received SIGTERM. Terminating subprocesses.
[2023-01-28 03:33:35,222] {subprocess.py:99} INFO - Sending SIGTERM signal to process group
[2023-01-28 03:33:35,235] {taskinstance.py:1700} ERROR - Task failed with exception
Traceback (most recent call last):
  File "/home/airflow/.local/lib/python3.7/site-packages/airflow/models/taskinstance.py", line 1329, in _run_raw_task
    self._execute_task_with_callbacks(context)
  File "/home/airflow/.local/lib/python3.7/site-packages/airflow/models/taskinstance.py", line 1455, in _execute_task_with_callbacks
    result = self._execute_task(context, self.task)
  File "/home/airflow/.local/lib/python3.7/site-packages/airflow/models/taskinstance.py", line 1511, in _execute_task
    result = execute_callable(context=context)
  File "/home/airflow/.local/lib/python3.7/site-packages/airflow/operators/bash.py", line 182, in execute
    cwd=self.cwd,
  File "/home/airflow/.local/lib/python3.7/site-packages/airflow/hooks/subprocess.py", line 87, in run_command
    for raw_line in iter(self.sub_process.stdout.readline, b''):
  File "/home/airflow/.local/lib/python3.7/site-packages/airflow/models/taskinstance.py", line 1410, in signal_handler
    raise AirflowException("Task received SIGTERM signal")
airflow.exceptions.AirflowException: Task received SIGTERM signal
[2023-01-28 03:33:35,257] {taskinstance.py:1277} INFO - Marking task as FAILED. dag_id=data_ingestion_fhv_dag, task_id=download_dataset_task, execution_date=20190101T000000, start_date=20230128T033320, end_date=20230128T033335
[2023-01-28 03:33:35,277] {standard_task_runner.py:92} ERROR - Failed to execute job 110 for task download_dataset_task
Traceback (most recent call last):
  File "/home/airflow/.local/lib/python3.7/site-packages/airflow/task/task_runner/standard_task_runner.py", line 85, in _start_by_fork
    args.func(args, dag=self.dag)
  File "/home/airflow/.local/lib/python3.7/site-packages/airflow/cli/cli_parser.py", line 48, in command
    return func(*args, **kwargs)
  File "/home/airflow/.local/lib/python3.7/site-packages/airflow/utils/cli.py", line 92, in wrapper
    return f(*args, **kwargs)
  File "/home/airflow/.local/lib/python3.7/site-packages/airflow/cli/commands/task_command.py", line 298, in task_run
    _run_task_by_selected_method(args, dag, ti)
  File "/home/airflow/.local/lib/python3.7/site-packages/airflow/cli/commands/task_command.py", line 107, in _run_task_by_selected_method
    _run_raw_task(args, ti)
  File "/home/airflow/.local/lib/python3.7/site-packages/airflow/cli/commands/task_command.py", line 184, in _run_raw_task
    error_file=args.error_file,
  File "/home/airflow/.local/lib/python3.7/site-packages/airflow/utils/session.py", line 70, in wrapper
    return func(*args, session=session, **kwargs)
  File "/home/airflow/.local/lib/python3.7/site-packages/airflow/models/taskinstance.py", line 1329, in _run_raw_task
    self._execute_task_with_callbacks(context)
  File "/home/airflow/.local/lib/python3.7/site-packages/airflow/models/taskinstance.py", line 1455, in _execute_task_with_callbacks
    result = self._execute_task(context, self.task)
  File "/home/airflow/.local/lib/python3.7/site-packages/airflow/models/taskinstance.py", line 1511, in _execute_task
    result = execute_callable(context=context)
  File "/home/airflow/.local/lib/python3.7/site-packages/airflow/operators/bash.py", line 182, in execute
    cwd=self.cwd,
  File "/home/airflow/.local/lib/python3.7/site-packages/airflow/hooks/subprocess.py", line 87, in run_command
    for raw_line in iter(self.sub_process.stdout.readline, b''):
  File "/home/airflow/.local/lib/python3.7/site-packages/airflow/models/taskinstance.py", line 1410, in signal_handler
    raise AirflowException("Task received SIGTERM signal")
airflow.exceptions.AirflowException: Task received SIGTERM signal
[2023-01-28 03:33:35,315] {process_utils.py:70} INFO - Process psutil.Process(pid=18926, status='terminated', exitcode=1, started='03:33:19') (18926) terminated with exit code 1
[2023-01-28 03:33:35,317] {process_utils.py:70} INFO - Process psutil.Process(pid=18927, status='terminated', started='03:33:19') (18927) terminated with exit code None
[2023-01-28 03:33:35,318] {process_utils.py:70} INFO - Process psutil.Process(pid=18928, status='terminated', started='03:33:19') (18928) terminated with exit code None
[2023-01-28 03:54:39,243] {taskinstance.py:1032} INFO - Dependencies all met for <TaskInstance: data_ingestion_fhv_dag.download_dataset_task scheduled__2019-01-01T00:00:00+00:00 [queued]>
[2023-01-28 03:54:39,256] {taskinstance.py:1032} INFO - Dependencies all met for <TaskInstance: data_ingestion_fhv_dag.download_dataset_task scheduled__2019-01-01T00:00:00+00:00 [queued]>
[2023-01-28 03:54:39,257] {taskinstance.py:1238} INFO - 
--------------------------------------------------------------------------------
[2023-01-28 03:54:39,257] {taskinstance.py:1239} INFO - Starting attempt 2 of 3
[2023-01-28 03:54:39,258] {taskinstance.py:1240} INFO - 
--------------------------------------------------------------------------------
[2023-01-28 03:54:39,269] {taskinstance.py:1259} INFO - Executing <Task(BashOperator): download_dataset_task> on 2019-01-01 00:00:00+00:00
[2023-01-28 03:54:39,282] {standard_task_runner.py:52} INFO - Started process 21960 to run task
[2023-01-28 03:54:39,286] {standard_task_runner.py:76} INFO - Running: ['***', 'tasks', 'run', 'data_ingestion_fhv_dag', 'download_dataset_task', 'scheduled__2019-01-01T00:00:00+00:00', '--job-id', '181', '--raw', '--subdir', 'DAGS_FOLDER/data_ingestion_fhv_dag.py', '--cfg-path', '/tmp/tmpg2vm8c0d', '--error-file', '/tmp/tmpn0xd96yc']
[2023-01-28 03:54:39,288] {standard_task_runner.py:77} INFO - Job 181: Subtask download_dataset_task
[2023-01-28 03:54:39,355] {logging_mixin.py:109} INFO - Running <TaskInstance: data_ingestion_fhv_dag.download_dataset_task scheduled__2019-01-01T00:00:00+00:00 [running]> on host adbf820de9e6
[2023-01-28 03:54:39,401] {logging_mixin.py:109} WARNING - /home/***/.local/lib/python3.7/site-packages/***/utils/context.py:152 AirflowContextDeprecationWarning: Accessing 'execution_date' from the template is deprecated and will be removed in a future version. Please use 'data_interval_start' or 'logical_date' instead.
[2023-01-28 03:54:39,425] {taskinstance.py:1426} INFO - Exporting the following env vars:
AIRFLOW_CTX_DAG_OWNER=***
AIRFLOW_CTX_DAG_ID=data_ingestion_fhv_dag
AIRFLOW_CTX_TASK_ID=download_dataset_task
AIRFLOW_CTX_EXECUTION_DATE=2019-01-01T00:00:00+00:00
AIRFLOW_CTX_DAG_RUN_ID=scheduled__2019-01-01T00:00:00+00:00
[2023-01-28 03:54:39,427] {subprocess.py:62} INFO - Tmp dir root location: 
 /tmp
[2023-01-28 03:54:39,429] {subprocess.py:74} INFO - Running command: ['bash', '-c', 'curl -sSLf https://d37ci6vzurychx.cloudfront.net/trip-data/fhv_tripdata_2019-01.parquet > /opt/***/fhv_tripdata_2019-01.parquet']
[2023-01-28 03:54:39,444] {subprocess.py:85} INFO - Output:
[2023-01-28 03:55:08,587] {subprocess.py:93} INFO - Command exited with return code 0
[2023-01-28 03:55:08,640] {taskinstance.py:1277} INFO - Marking task as SUCCESS. dag_id=data_ingestion_fhv_dag, task_id=download_dataset_task, execution_date=20190101T000000, start_date=20230128T035439, end_date=20230128T035508
[2023-01-28 03:55:08,706] {local_task_job.py:154} INFO - Task exited with return code 0
[2023-01-28 03:55:08,757] {local_task_job.py:264} INFO - 1 downstream tasks scheduled from follow-on schedule check
