[2023-01-29 12:19:05,191] {taskinstance.py:1032} INFO - Dependencies all met for <TaskInstance: data_ingestion_gcs_dag.cast_parquet_columns_task scheduled__2019-01-01T00:00:00+00:00 [queued]>
[2023-01-29 12:19:05,202] {taskinstance.py:1032} INFO - Dependencies all met for <TaskInstance: data_ingestion_gcs_dag.cast_parquet_columns_task scheduled__2019-01-01T00:00:00+00:00 [queued]>
[2023-01-29 12:19:05,203] {taskinstance.py:1238} INFO - 
--------------------------------------------------------------------------------
[2023-01-29 12:19:05,203] {taskinstance.py:1239} INFO - Starting attempt 3 of 4
[2023-01-29 12:19:05,204] {taskinstance.py:1240} INFO - 
--------------------------------------------------------------------------------
[2023-01-29 12:19:05,215] {taskinstance.py:1259} INFO - Executing <Task(PythonOperator): cast_parquet_columns_task> on 2019-01-01 00:00:00+00:00
[2023-01-29 12:19:05,221] {standard_task_runner.py:52} INFO - Started process 3022 to run task
[2023-01-29 12:19:05,225] {standard_task_runner.py:76} INFO - Running: ['***', 'tasks', 'run', 'data_ingestion_gcs_dag', 'cast_parquet_columns_task', 'scheduled__2019-01-01T00:00:00+00:00', '--job-id', '358', '--raw', '--subdir', 'DAGS_FOLDER/data_ingestion_gcs_dag.py', '--cfg-path', '/tmp/tmpabskyjtu', '--error-file', '/tmp/tmpwevcdyn9']
[2023-01-29 12:19:05,226] {standard_task_runner.py:77} INFO - Job 358: Subtask cast_parquet_columns_task
[2023-01-29 12:19:05,281] {logging_mixin.py:109} INFO - Running <TaskInstance: data_ingestion_gcs_dag.cast_parquet_columns_task scheduled__2019-01-01T00:00:00+00:00 [running]> on host 2530f37057aa
[2023-01-29 12:19:05,330] {taskinstance.py:1426} INFO - Exporting the following env vars:
AIRFLOW_CTX_DAG_OWNER=***
AIRFLOW_CTX_DAG_ID=data_ingestion_gcs_dag
AIRFLOW_CTX_TASK_ID=cast_parquet_columns_task
AIRFLOW_CTX_EXECUTION_DATE=2019-01-01T00:00:00+00:00
AIRFLOW_CTX_DAG_RUN_ID=scheduled__2019-01-01T00:00:00+00:00
[2023-01-29 12:19:05,332] {logging_mixin.py:109} INFO - /opt/***
[2023-01-29 12:19:05,334] {taskinstance.py:1700} ERROR - Task failed with exception
Traceback (most recent call last):
  File "/home/airflow/.local/lib/python3.7/site-packages/airflow/models/taskinstance.py", line 1329, in _run_raw_task
    self._execute_task_with_callbacks(context)
  File "/home/airflow/.local/lib/python3.7/site-packages/airflow/models/taskinstance.py", line 1455, in _execute_task_with_callbacks
    result = self._execute_task(context, self.task)
  File "/home/airflow/.local/lib/python3.7/site-packages/airflow/models/taskinstance.py", line 1511, in _execute_task
    result = execute_callable(context=context)
  File "/home/airflow/.local/lib/python3.7/site-packages/airflow/operators/python.py", line 174, in execute
    return_value = self.execute_callable()
  File "/home/airflow/.local/lib/python3.7/site-packages/airflow/operators/python.py", line 185, in execute_callable
    return self.python_callable(*self.op_args, **self.op_kwargs)
  File "/opt/airflow/dags/data_ingestion_gcs_dag.py", line 62, in cast_parquet_columns
    table = pv.read_csv(dataset_file)
  File "pyarrow/_csv.pyx", line 862, in pyarrow._csv.read_csv
  File "pyarrow/_csv.pyx", line 755, in pyarrow._csv._get_reader
  File "pyarrow/io.pxi", line 1551, in pyarrow.lib.get_input_stream
  File "pyarrow/io.pxi", line 1522, in pyarrow.lib.get_native_file
  File "pyarrow/io.pxi", line 886, in pyarrow.lib.OSFile.__cinit__
  File "pyarrow/io.pxi", line 896, in pyarrow.lib.OSFile._open_readable
  File "pyarrow/error.pxi", line 143, in pyarrow.lib.pyarrow_internal_check_status
  File "pyarrow/error.pxi", line 112, in pyarrow.lib.check_status
FileNotFoundError: [Errno 2] Failed to open local file 'fhv_tripdata_{{ execution_date.strftime('%Y-%m') }}.parquet'. Detail: [errno 2] No such file or directory
[2023-01-29 12:19:05,350] {taskinstance.py:1277} INFO - Marking task as UP_FOR_RETRY. dag_id=data_ingestion_gcs_dag, task_id=cast_parquet_columns_task, execution_date=20190101T000000, start_date=20230129T121905, end_date=20230129T121905
[2023-01-29 12:19:05,362] {standard_task_runner.py:92} ERROR - Failed to execute job 358 for task cast_parquet_columns_task
Traceback (most recent call last):
  File "/home/airflow/.local/lib/python3.7/site-packages/airflow/task/task_runner/standard_task_runner.py", line 85, in _start_by_fork
    args.func(args, dag=self.dag)
  File "/home/airflow/.local/lib/python3.7/site-packages/airflow/cli/cli_parser.py", line 48, in command
    return func(*args, **kwargs)
  File "/home/airflow/.local/lib/python3.7/site-packages/airflow/utils/cli.py", line 92, in wrapper
    return f(*args, **kwargs)
  File "/home/airflow/.local/lib/python3.7/site-packages/airflow/cli/commands/task_command.py", line 298, in task_run
    _run_task_by_selected_method(args, dag, ti)
  File "/home/airflow/.local/lib/python3.7/site-packages/airflow/cli/commands/task_command.py", line 107, in _run_task_by_selected_method
    _run_raw_task(args, ti)
  File "/home/airflow/.local/lib/python3.7/site-packages/airflow/cli/commands/task_command.py", line 184, in _run_raw_task
    error_file=args.error_file,
  File "/home/airflow/.local/lib/python3.7/site-packages/airflow/utils/session.py", line 70, in wrapper
    return func(*args, session=session, **kwargs)
  File "/home/airflow/.local/lib/python3.7/site-packages/airflow/models/taskinstance.py", line 1329, in _run_raw_task
    self._execute_task_with_callbacks(context)
  File "/home/airflow/.local/lib/python3.7/site-packages/airflow/models/taskinstance.py", line 1455, in _execute_task_with_callbacks
    result = self._execute_task(context, self.task)
  File "/home/airflow/.local/lib/python3.7/site-packages/airflow/models/taskinstance.py", line 1511, in _execute_task
    result = execute_callable(context=context)
  File "/home/airflow/.local/lib/python3.7/site-packages/airflow/operators/python.py", line 174, in execute
    return_value = self.execute_callable()
  File "/home/airflow/.local/lib/python3.7/site-packages/airflow/operators/python.py", line 185, in execute_callable
    return self.python_callable(*self.op_args, **self.op_kwargs)
  File "/opt/airflow/dags/data_ingestion_gcs_dag.py", line 62, in cast_parquet_columns
    table = pv.read_csv(dataset_file)
  File "pyarrow/_csv.pyx", line 862, in pyarrow._csv.read_csv
  File "pyarrow/_csv.pyx", line 755, in pyarrow._csv._get_reader
  File "pyarrow/io.pxi", line 1551, in pyarrow.lib.get_input_stream
  File "pyarrow/io.pxi", line 1522, in pyarrow.lib.get_native_file
  File "pyarrow/io.pxi", line 886, in pyarrow.lib.OSFile.__cinit__
  File "pyarrow/io.pxi", line 896, in pyarrow.lib.OSFile._open_readable
  File "pyarrow/error.pxi", line 143, in pyarrow.lib.pyarrow_internal_check_status
  File "pyarrow/error.pxi", line 112, in pyarrow.lib.check_status
FileNotFoundError: [Errno 2] Failed to open local file 'fhv_tripdata_{{ execution_date.strftime('%Y-%m') }}.parquet'. Detail: [errno 2] No such file or directory
[2023-01-29 12:19:05,402] {local_task_job.py:154} INFO - Task exited with return code 1
[2023-01-29 12:19:05,435] {local_task_job.py:264} INFO - 0 downstream tasks scheduled from follow-on schedule check
[2023-01-29 12:43:47,298] {taskinstance.py:1032} INFO - Dependencies all met for <TaskInstance: data_ingestion_gcs_dag.cast_parquet_columns_task scheduled__2019-01-01T00:00:00+00:00 [queued]>
[2023-01-29 12:43:47,312] {taskinstance.py:1032} INFO - Dependencies all met for <TaskInstance: data_ingestion_gcs_dag.cast_parquet_columns_task scheduled__2019-01-01T00:00:00+00:00 [queued]>
[2023-01-29 12:43:47,313] {taskinstance.py:1238} INFO - 
--------------------------------------------------------------------------------
[2023-01-29 12:43:47,314] {taskinstance.py:1239} INFO - Starting attempt 3 of 4
[2023-01-29 12:43:47,315] {taskinstance.py:1240} INFO - 
--------------------------------------------------------------------------------
[2023-01-29 12:43:47,326] {taskinstance.py:1259} INFO - Executing <Task(PythonOperator): cast_parquet_columns_task> on 2019-01-01 00:00:00+00:00
[2023-01-29 12:43:47,331] {standard_task_runner.py:52} INFO - Started process 7020 to run task
[2023-01-29 12:43:47,334] {standard_task_runner.py:76} INFO - Running: ['***', 'tasks', 'run', 'data_ingestion_gcs_dag', 'cast_parquet_columns_task', 'scheduled__2019-01-01T00:00:00+00:00', '--job-id', '402', '--raw', '--subdir', 'DAGS_FOLDER/data_ingestion_gcs_dag.py', '--cfg-path', '/tmp/tmpht2jmd0t', '--error-file', '/tmp/tmpw1v2r1cv']
[2023-01-29 12:43:47,336] {standard_task_runner.py:77} INFO - Job 402: Subtask cast_parquet_columns_task
[2023-01-29 12:43:47,390] {logging_mixin.py:109} INFO - Running <TaskInstance: data_ingestion_gcs_dag.cast_parquet_columns_task scheduled__2019-01-01T00:00:00+00:00 [running]> on host 2530f37057aa
[2023-01-29 12:43:47,432] {logging_mixin.py:109} WARNING - /home/***/.local/lib/python3.7/site-packages/***/utils/context.py:152 AirflowContextDeprecationWarning: Accessing 'execution_date' from the template is deprecated and will be removed in a future version. Please use 'data_interval_start' or 'logical_date' instead.
[2023-01-29 12:43:47,453] {taskinstance.py:1426} INFO - Exporting the following env vars:
AIRFLOW_CTX_DAG_OWNER=***
AIRFLOW_CTX_DAG_ID=data_ingestion_gcs_dag
AIRFLOW_CTX_TASK_ID=cast_parquet_columns_task
AIRFLOW_CTX_EXECUTION_DATE=2019-01-01T00:00:00+00:00
AIRFLOW_CTX_DAG_RUN_ID=scheduled__2019-01-01T00:00:00+00:00
[2023-01-29 12:43:47,455] {logging_mixin.py:109} INFO - /opt/***
[2023-01-29 12:43:49,139] {local_task_job.py:154} INFO - Task exited with return code Negsignal.SIGKILL
[2023-01-29 12:43:49,203] {taskinstance.py:1277} INFO - Marking task as UP_FOR_RETRY. dag_id=data_ingestion_gcs_dag, task_id=cast_parquet_columns_task, execution_date=20190101T000000, start_date=20230129T124347, end_date=20230129T124349
[2023-01-29 12:43:49,246] {local_task_job.py:264} INFO - 0 downstream tasks scheduled from follow-on schedule check
[2023-01-29 13:02:11,720] {taskinstance.py:1032} INFO - Dependencies all met for <TaskInstance: data_ingestion_gcs_dag.cast_parquet_columns_task scheduled__2019-01-01T00:00:00+00:00 [queued]>
[2023-01-29 13:02:11,732] {taskinstance.py:1032} INFO - Dependencies all met for <TaskInstance: data_ingestion_gcs_dag.cast_parquet_columns_task scheduled__2019-01-01T00:00:00+00:00 [queued]>
[2023-01-29 13:02:11,732] {taskinstance.py:1238} INFO - 
--------------------------------------------------------------------------------
[2023-01-29 13:02:11,733] {taskinstance.py:1239} INFO - Starting attempt 3 of 4
[2023-01-29 13:02:11,734] {taskinstance.py:1240} INFO - 
--------------------------------------------------------------------------------
[2023-01-29 13:02:11,746] {taskinstance.py:1259} INFO - Executing <Task(PythonOperator): cast_parquet_columns_task> on 2019-01-01 00:00:00+00:00
[2023-01-29 13:02:11,751] {standard_task_runner.py:52} INFO - Started process 1979 to run task
[2023-01-29 13:02:11,755] {standard_task_runner.py:76} INFO - Running: ['***', 'tasks', 'run', 'data_ingestion_gcs_dag', 'cast_parquet_columns_task', 'scheduled__2019-01-01T00:00:00+00:00', '--job-id', '451', '--raw', '--subdir', 'DAGS_FOLDER/data_ingestion_gcs_dag.py', '--cfg-path', '/tmp/tmpv8ycvlww', '--error-file', '/tmp/tmpm_zac0qo']
[2023-01-29 13:02:11,758] {standard_task_runner.py:77} INFO - Job 451: Subtask cast_parquet_columns_task
[2023-01-29 13:02:11,829] {logging_mixin.py:109} INFO - Running <TaskInstance: data_ingestion_gcs_dag.cast_parquet_columns_task scheduled__2019-01-01T00:00:00+00:00 [running]> on host 2530f37057aa
[2023-01-29 13:02:11,882] {logging_mixin.py:109} WARNING - /home/***/.local/lib/python3.7/site-packages/***/utils/context.py:152 AirflowContextDeprecationWarning: Accessing 'execution_date' from the template is deprecated and will be removed in a future version. Please use 'data_interval_start' or 'logical_date' instead.
[2023-01-29 13:02:11,907] {taskinstance.py:1426} INFO - Exporting the following env vars:
AIRFLOW_CTX_DAG_OWNER=***
AIRFLOW_CTX_DAG_ID=data_ingestion_gcs_dag
AIRFLOW_CTX_TASK_ID=cast_parquet_columns_task
AIRFLOW_CTX_EXECUTION_DATE=2019-01-01T00:00:00+00:00
AIRFLOW_CTX_DAG_RUN_ID=scheduled__2019-01-01T00:00:00+00:00
[2023-01-29 13:02:11,909] {logging_mixin.py:109} WARNING - --- Logging error ---
[2023-01-29 13:02:11,913] {logging_mixin.py:109} WARNING - Traceback (most recent call last):
[2023-01-29 13:02:11,914] {logging_mixin.py:109} WARNING -   File "/usr/local/lib/python3.7/logging/__init__.py", line 1025, in emit
    msg = self.format(record)
[2023-01-29 13:02:11,915] {logging_mixin.py:109} WARNING -   File "/usr/local/lib/python3.7/logging/__init__.py", line 869, in format
    return fmt.format(record)
[2023-01-29 13:02:11,916] {logging_mixin.py:109} WARNING -   File "/usr/local/lib/python3.7/logging/__init__.py", line 608, in format
    record.message = record.getMessage()
[2023-01-29 13:02:11,917] {logging_mixin.py:109} WARNING -   File "/usr/local/lib/python3.7/logging/__init__.py", line 369, in getMessage
    msg = msg % self.args
[2023-01-29 13:02:11,918] {logging_mixin.py:109} WARNING - TypeError: not all arguments converted during string formatting
[2023-01-29 13:02:11,919] {logging_mixin.py:109} WARNING - Call stack:
[2023-01-29 13:02:11,929] {logging_mixin.py:109} WARNING -   File "/home/***/.local/bin/***", line 8, in <module>
    sys.exit(main())
[2023-01-29 13:02:11,931] {logging_mixin.py:109} WARNING -   File "/home/***/.local/lib/python3.7/site-packages/***/__main__.py", line 48, in main
    args.func(args)
[2023-01-29 13:02:11,932] {logging_mixin.py:109} WARNING -   File "/home/***/.local/lib/python3.7/site-packages/***/cli/cli_parser.py", line 48, in command
    return func(*args, **kwargs)
[2023-01-29 13:02:11,933] {logging_mixin.py:109} WARNING -   File "/home/***/.local/lib/python3.7/site-packages/***/utils/cli.py", line 92, in wrapper
    return f(*args, **kwargs)
[2023-01-29 13:02:11,934] {logging_mixin.py:109} WARNING -   File "/home/***/.local/lib/python3.7/site-packages/***/cli/commands/scheduler_command.py", line 75, in scheduler
    _run_scheduler_job(args=args)
[2023-01-29 13:02:11,935] {logging_mixin.py:109} WARNING -   File "/home/***/.local/lib/python3.7/site-packages/***/cli/commands/scheduler_command.py", line 46, in _run_scheduler_job
    job.run()
[2023-01-29 13:02:11,936] {logging_mixin.py:109} WARNING -   File "/home/***/.local/lib/python3.7/site-packages/***/jobs/base_job.py", line 245, in run
    self._execute()
[2023-01-29 13:02:11,937] {logging_mixin.py:109} WARNING -   File "/home/***/.local/lib/python3.7/site-packages/***/jobs/scheduler_job.py", line 620, in _execute
    self.executor.start()
[2023-01-29 13:02:11,938] {logging_mixin.py:109} WARNING -   File "/home/***/.local/lib/python3.7/site-packages/***/executors/local_executor.py", line 356, in start
    self.impl.start()
[2023-01-29 13:02:11,938] {logging_mixin.py:109} WARNING -   File "/home/***/.local/lib/python3.7/site-packages/***/executors/local_executor.py", line 298, in start
    worker.start()
[2023-01-29 13:02:11,939] {logging_mixin.py:109} WARNING -   File "/usr/local/lib/python3.7/multiprocessing/process.py", line 112, in start
    self._popen = self._Popen(self)
[2023-01-29 13:02:11,940] {logging_mixin.py:109} WARNING -   File "/usr/local/lib/python3.7/multiprocessing/context.py", line 223, in _Popen
    return _default_context.get_context().Process._Popen(process_obj)
[2023-01-29 13:02:11,941] {logging_mixin.py:109} WARNING -   File "/usr/local/lib/python3.7/multiprocessing/context.py", line 277, in _Popen
    return Popen(process_obj)
[2023-01-29 13:02:11,942] {logging_mixin.py:109} WARNING -   File "/usr/local/lib/python3.7/multiprocessing/popen_fork.py", line 20, in __init__
    self._launch(process_obj)
[2023-01-29 13:02:11,943] {logging_mixin.py:109} WARNING -   File "/usr/local/lib/python3.7/multiprocessing/popen_fork.py", line 74, in _launch
    code = process_obj._bootstrap()
[2023-01-29 13:02:11,944] {logging_mixin.py:109} WARNING -   File "/usr/local/lib/python3.7/multiprocessing/process.py", line 297, in _bootstrap
    self.run()
[2023-01-29 13:02:11,945] {logging_mixin.py:109} WARNING -   File "/home/***/.local/lib/python3.7/site-packages/***/executors/local_executor.py", line 67, in run
    return super().run()
[2023-01-29 13:02:11,946] {logging_mixin.py:109} WARNING -   File "/usr/local/lib/python3.7/multiprocessing/process.py", line 99, in run
    self._target(*self._args, **self._kwargs)
[2023-01-29 13:02:11,949] {logging_mixin.py:109} WARNING -   File "/home/***/.local/lib/python3.7/site-packages/***/executors/local_executor.py", line 190, in do_work
    self.execute_work(key=key, command=command)
[2023-01-29 13:02:11,950] {logging_mixin.py:109} WARNING -   File "/home/***/.local/lib/python3.7/site-packages/***/executors/local_executor.py", line 84, in execute_work
    state = self._execute_work_in_fork(command)
[2023-01-29 13:02:11,951] {logging_mixin.py:109} WARNING -   File "/home/***/.local/lib/python3.7/site-packages/***/executors/local_executor.py", line 124, in _execute_work_in_fork
    args.func(args)
[2023-01-29 13:02:11,952] {logging_mixin.py:109} WARNING -   File "/home/***/.local/lib/python3.7/site-packages/***/cli/cli_parser.py", line 48, in command
    return func(*args, **kwargs)
[2023-01-29 13:02:11,954] {logging_mixin.py:109} WARNING -   File "/home/***/.local/lib/python3.7/site-packages/***/utils/cli.py", line 92, in wrapper
    return f(*args, **kwargs)
[2023-01-29 13:02:11,956] {logging_mixin.py:109} WARNING -   File "/home/***/.local/lib/python3.7/site-packages/***/cli/commands/task_command.py", line 298, in task_run
    _run_task_by_selected_method(args, dag, ti)
[2023-01-29 13:02:11,960] {logging_mixin.py:109} WARNING -   File "/home/***/.local/lib/python3.7/site-packages/***/cli/commands/task_command.py", line 105, in _run_task_by_selected_method
    _run_task_by_local_task_job(args, ti)
[2023-01-29 13:02:11,963] {logging_mixin.py:109} WARNING -   File "/home/***/.local/lib/python3.7/site-packages/***/cli/commands/task_command.py", line 163, in _run_task_by_local_task_job
    run_job.run()
[2023-01-29 13:02:11,964] {logging_mixin.py:109} WARNING -   File "/home/***/.local/lib/python3.7/site-packages/***/jobs/base_job.py", line 245, in run
    self._execute()
[2023-01-29 13:02:11,965] {logging_mixin.py:109} WARNING -   File "/home/***/.local/lib/python3.7/site-packages/***/jobs/local_task_job.py", line 103, in _execute
    self.task_runner.start()
[2023-01-29 13:02:11,967] {logging_mixin.py:109} WARNING -   File "/home/***/.local/lib/python3.7/site-packages/***/task/task_runner/standard_task_runner.py", line 41, in start
    self.process = self._start_by_fork()
[2023-01-29 13:02:11,968] {logging_mixin.py:109} WARNING -   File "/home/***/.local/lib/python3.7/site-packages/***/task/task_runner/standard_task_runner.py", line 85, in _start_by_fork
    args.func(args, dag=self.dag)
[2023-01-29 13:02:11,969] {logging_mixin.py:109} WARNING -   File "/home/***/.local/lib/python3.7/site-packages/***/cli/cli_parser.py", line 48, in command
    return func(*args, **kwargs)
[2023-01-29 13:02:11,969] {logging_mixin.py:109} WARNING -   File "/home/***/.local/lib/python3.7/site-packages/***/utils/cli.py", line 92, in wrapper
    return f(*args, **kwargs)
[2023-01-29 13:02:11,970] {logging_mixin.py:109} WARNING -   File "/home/***/.local/lib/python3.7/site-packages/***/cli/commands/task_command.py", line 298, in task_run
    _run_task_by_selected_method(args, dag, ti)
[2023-01-29 13:02:11,971] {logging_mixin.py:109} WARNING -   File "/home/***/.local/lib/python3.7/site-packages/***/cli/commands/task_command.py", line 107, in _run_task_by_selected_method
    _run_raw_task(args, ti)
[2023-01-29 13:02:11,972] {logging_mixin.py:109} WARNING -   File "/home/***/.local/lib/python3.7/site-packages/***/cli/commands/task_command.py", line 184, in _run_raw_task
    error_file=args.error_file,
[2023-01-29 13:02:11,973] {logging_mixin.py:109} WARNING -   File "/home/***/.local/lib/python3.7/site-packages/***/utils/session.py", line 70, in wrapper
    return func(*args, session=session, **kwargs)
[2023-01-29 13:02:11,973] {logging_mixin.py:109} WARNING -   File "/home/***/.local/lib/python3.7/site-packages/***/models/taskinstance.py", line 1329, in _run_raw_task
    self._execute_task_with_callbacks(context)
[2023-01-29 13:02:11,974] {logging_mixin.py:109} WARNING -   File "/home/***/.local/lib/python3.7/site-packages/***/models/taskinstance.py", line 1455, in _execute_task_with_callbacks
    result = self._execute_task(context, self.task)
[2023-01-29 13:02:11,976] {logging_mixin.py:109} WARNING -   File "/home/***/.local/lib/python3.7/site-packages/***/models/taskinstance.py", line 1511, in _execute_task
    result = execute_callable(context=context)
[2023-01-29 13:02:11,976] {logging_mixin.py:109} WARNING -   File "/home/***/.local/lib/python3.7/site-packages/***/operators/python.py", line 174, in execute
    return_value = self.execute_callable()
[2023-01-29 13:02:11,977] {logging_mixin.py:109} WARNING -   File "/home/***/.local/lib/python3.7/site-packages/***/operators/python.py", line 185, in execute_callable
    return self.python_callable(*self.op_args, **self.op_kwargs)
[2023-01-29 13:02:11,978] {logging_mixin.py:109} WARNING -   File "/opt/***/dags/data_ingestion_gcs_dag.py", line 62, in cast_parquet_columns
    logging.info('local_file',local_file)
[2023-01-29 13:02:11,979] {logging_mixin.py:109} WARNING -   File "/usr/local/lib/python3.7/logging/__init__.py", line 1992, in info
    root.info(msg, *args, **kwargs)
[2023-01-29 13:02:11,980] {logging_mixin.py:109} WARNING -   File "/usr/local/lib/python3.7/logging/__init__.py", line 1378, in info
    self._log(INFO, msg, args, **kwargs)
[2023-01-29 13:02:11,980] {logging_mixin.py:109} WARNING -   File "/usr/local/lib/python3.7/logging/__init__.py", line 1514, in _log
    self.handle(record)
[2023-01-29 13:02:11,981] {logging_mixin.py:109} WARNING -   File "/usr/local/lib/python3.7/logging/__init__.py", line 1524, in handle
    self.callHandlers(record)
[2023-01-29 13:02:11,982] {logging_mixin.py:109} WARNING -   File "/usr/local/lib/python3.7/logging/__init__.py", line 1586, in callHandlers
    hdlr.handle(record)
[2023-01-29 13:02:11,983] {logging_mixin.py:109} WARNING -   File "/usr/local/lib/python3.7/logging/__init__.py", line 894, in handle
    self.emit(record)
[2023-01-29 13:02:11,983] {logging_mixin.py:109} WARNING -   File "/home/***/.local/lib/python3.7/site-packages/***/utils/log/file_task_handler.py", line 67, in emit
    self.handler.emit(record)
[2023-01-29 13:02:11,984] {logging_mixin.py:109} WARNING - Message: 'local_file'
Arguments: ('/opt/***/fhv_tripdata_2019-01.parquet',)
[2023-01-29 13:02:13,291] {local_task_job.py:154} INFO - Task exited with return code Negsignal.SIGKILL
[2023-01-29 13:02:13,387] {taskinstance.py:1277} INFO - Marking task as UP_FOR_RETRY. dag_id=data_ingestion_gcs_dag, task_id=cast_parquet_columns_task, execution_date=20190101T000000, start_date=20230129T130211, end_date=20230129T130213
[2023-01-29 13:02:13,476] {local_task_job.py:264} INFO - 0 downstream tasks scheduled from follow-on schedule check
