[2023-01-29 12:48:59,421] {taskinstance.py:1032} INFO - Dependencies all met for <TaskInstance: data_ingestion_gcs_dag.cast_parquet_columns_task scheduled__2019-01-01T00:00:00+00:00 [queued]>
[2023-01-29 12:48:59,434] {taskinstance.py:1032} INFO - Dependencies all met for <TaskInstance: data_ingestion_gcs_dag.cast_parquet_columns_task scheduled__2019-01-01T00:00:00+00:00 [queued]>
[2023-01-29 12:48:59,435] {taskinstance.py:1238} INFO - 
--------------------------------------------------------------------------------
[2023-01-29 12:48:59,436] {taskinstance.py:1239} INFO - Starting attempt 7 of 8
[2023-01-29 12:48:59,437] {taskinstance.py:1240} INFO - 
--------------------------------------------------------------------------------
[2023-01-29 12:48:59,451] {taskinstance.py:1259} INFO - Executing <Task(PythonOperator): cast_parquet_columns_task> on 2019-01-01 00:00:00+00:00
[2023-01-29 12:48:59,457] {standard_task_runner.py:52} INFO - Started process 8101 to run task
[2023-01-29 12:48:59,462] {standard_task_runner.py:76} INFO - Running: ['***', 'tasks', 'run', 'data_ingestion_gcs_dag', 'cast_parquet_columns_task', 'scheduled__2019-01-01T00:00:00+00:00', '--job-id', '432', '--raw', '--subdir', 'DAGS_FOLDER/data_ingestion_gcs_dag.py', '--cfg-path', '/tmp/tmpq73ylbrq', '--error-file', '/tmp/tmpeoa_frr5']
[2023-01-29 12:48:59,463] {standard_task_runner.py:77} INFO - Job 432: Subtask cast_parquet_columns_task
[2023-01-29 12:48:59,524] {logging_mixin.py:109} INFO - Running <TaskInstance: data_ingestion_gcs_dag.cast_parquet_columns_task scheduled__2019-01-01T00:00:00+00:00 [running]> on host 2530f37057aa
[2023-01-29 12:48:59,564] {logging_mixin.py:109} WARNING - /home/***/.local/lib/python3.7/site-packages/***/utils/context.py:152 AirflowContextDeprecationWarning: Accessing 'execution_date' from the template is deprecated and will be removed in a future version. Please use 'data_interval_start' or 'logical_date' instead.
[2023-01-29 12:48:59,585] {taskinstance.py:1426} INFO - Exporting the following env vars:
AIRFLOW_CTX_DAG_OWNER=***
AIRFLOW_CTX_DAG_ID=data_ingestion_gcs_dag
AIRFLOW_CTX_TASK_ID=cast_parquet_columns_task
AIRFLOW_CTX_EXECUTION_DATE=2019-01-01T00:00:00+00:00
AIRFLOW_CTX_DAG_RUN_ID=scheduled__2019-01-01T00:00:00+00:00
[2023-01-29 12:48:59,587] {logging_mixin.py:109} INFO - /opt/***
[2023-01-29 12:49:05,840] {local_task_job.py:154} INFO - Task exited with return code Negsignal.SIGKILL
[2023-01-29 12:49:05,920] {taskinstance.py:1277} INFO - Marking task as UP_FOR_RETRY. dag_id=data_ingestion_gcs_dag, task_id=cast_parquet_columns_task, execution_date=20190101T000000, start_date=20230129T124859, end_date=20230129T124905
[2023-01-29 12:49:05,991] {local_task_job.py:264} INFO - 0 downstream tasks scheduled from follow-on schedule check
[2023-01-29 13:15:15,325] {taskinstance.py:1032} INFO - Dependencies all met for <TaskInstance: data_ingestion_gcs_dag.cast_parquet_columns_task scheduled__2019-01-01T00:00:00+00:00 [queued]>
[2023-01-29 13:15:15,336] {taskinstance.py:1032} INFO - Dependencies all met for <TaskInstance: data_ingestion_gcs_dag.cast_parquet_columns_task scheduled__2019-01-01T00:00:00+00:00 [queued]>
[2023-01-29 13:15:15,336] {taskinstance.py:1238} INFO - 
--------------------------------------------------------------------------------
[2023-01-29 13:15:15,337] {taskinstance.py:1239} INFO - Starting attempt 7 of 8
[2023-01-29 13:15:15,337] {taskinstance.py:1240} INFO - 
--------------------------------------------------------------------------------
[2023-01-29 13:15:15,346] {taskinstance.py:1259} INFO - Executing <Task(PythonOperator): cast_parquet_columns_task> on 2019-01-01 00:00:00+00:00
[2023-01-29 13:15:15,350] {standard_task_runner.py:52} INFO - Started process 220 to run task
[2023-01-29 13:15:15,353] {standard_task_runner.py:76} INFO - Running: ['***', 'tasks', 'run', 'data_ingestion_gcs_dag', 'cast_parquet_columns_task', 'scheduled__2019-01-01T00:00:00+00:00', '--job-id', '489', '--raw', '--subdir', 'DAGS_FOLDER/data_ingestion_gcs_dag.py', '--cfg-path', '/tmp/tmp959p9wgi', '--error-file', '/tmp/tmpon4lmj0j']
[2023-01-29 13:15:15,355] {standard_task_runner.py:77} INFO - Job 489: Subtask cast_parquet_columns_task
[2023-01-29 13:15:15,399] {logging_mixin.py:109} INFO - Running <TaskInstance: data_ingestion_gcs_dag.cast_parquet_columns_task scheduled__2019-01-01T00:00:00+00:00 [running]> on host 2530f37057aa
[2023-01-29 13:15:15,439] {logging_mixin.py:109} WARNING - /home/***/.local/lib/python3.7/site-packages/***/utils/context.py:152 AirflowContextDeprecationWarning: Accessing 'execution_date' from the template is deprecated and will be removed in a future version. Please use 'data_interval_start' or 'logical_date' instead.
[2023-01-29 13:15:15,459] {taskinstance.py:1426} INFO - Exporting the following env vars:
AIRFLOW_CTX_DAG_OWNER=***
AIRFLOW_CTX_DAG_ID=data_ingestion_gcs_dag
AIRFLOW_CTX_TASK_ID=cast_parquet_columns_task
AIRFLOW_CTX_EXECUTION_DATE=2019-01-01T00:00:00+00:00
AIRFLOW_CTX_DAG_RUN_ID=scheduled__2019-01-01T00:00:00+00:00
[2023-01-29 13:15:15,461] {logging_mixin.py:109} WARNING - --- Logging error ---
[2023-01-29 13:15:15,462] {logging_mixin.py:109} WARNING - Traceback (most recent call last):
[2023-01-29 13:15:15,463] {logging_mixin.py:109} WARNING -   File "/usr/local/lib/python3.7/logging/__init__.py", line 1025, in emit
    msg = self.format(record)
[2023-01-29 13:15:15,463] {logging_mixin.py:109} WARNING -   File "/usr/local/lib/python3.7/logging/__init__.py", line 869, in format
    return fmt.format(record)
[2023-01-29 13:15:15,464] {logging_mixin.py:109} WARNING -   File "/usr/local/lib/python3.7/logging/__init__.py", line 608, in format
    record.message = record.getMessage()
[2023-01-29 13:15:15,464] {logging_mixin.py:109} WARNING -   File "/usr/local/lib/python3.7/logging/__init__.py", line 369, in getMessage
    msg = msg % self.args
[2023-01-29 13:15:15,465] {logging_mixin.py:109} WARNING - TypeError: not all arguments converted during string formatting
[2023-01-29 13:15:15,465] {logging_mixin.py:109} WARNING - Call stack:
[2023-01-29 13:15:15,473] {logging_mixin.py:109} WARNING -   File "/home/***/.local/bin/***", line 8, in <module>
    sys.exit(main())
[2023-01-29 13:15:15,473] {logging_mixin.py:109} WARNING -   File "/home/***/.local/lib/python3.7/site-packages/***/__main__.py", line 48, in main
    args.func(args)
[2023-01-29 13:15:15,474] {logging_mixin.py:109} WARNING -   File "/home/***/.local/lib/python3.7/site-packages/***/cli/cli_parser.py", line 48, in command
    return func(*args, **kwargs)
[2023-01-29 13:15:15,474] {logging_mixin.py:109} WARNING -   File "/home/***/.local/lib/python3.7/site-packages/***/utils/cli.py", line 92, in wrapper
    return f(*args, **kwargs)
[2023-01-29 13:15:15,475] {logging_mixin.py:109} WARNING -   File "/home/***/.local/lib/python3.7/site-packages/***/cli/commands/scheduler_command.py", line 75, in scheduler
    _run_scheduler_job(args=args)
[2023-01-29 13:15:15,475] {logging_mixin.py:109} WARNING -   File "/home/***/.local/lib/python3.7/site-packages/***/cli/commands/scheduler_command.py", line 46, in _run_scheduler_job
    job.run()
[2023-01-29 13:15:15,475] {logging_mixin.py:109} WARNING -   File "/home/***/.local/lib/python3.7/site-packages/***/jobs/base_job.py", line 245, in run
    self._execute()
[2023-01-29 13:15:15,476] {logging_mixin.py:109} WARNING -   File "/home/***/.local/lib/python3.7/site-packages/***/jobs/scheduler_job.py", line 620, in _execute
    self.executor.start()
[2023-01-29 13:15:15,476] {logging_mixin.py:109} WARNING -   File "/home/***/.local/lib/python3.7/site-packages/***/executors/local_executor.py", line 356, in start
    self.impl.start()
[2023-01-29 13:15:15,477] {logging_mixin.py:109} WARNING -   File "/home/***/.local/lib/python3.7/site-packages/***/executors/local_executor.py", line 298, in start
    worker.start()
[2023-01-29 13:15:15,477] {logging_mixin.py:109} WARNING -   File "/usr/local/lib/python3.7/multiprocessing/process.py", line 112, in start
    self._popen = self._Popen(self)
[2023-01-29 13:15:15,478] {logging_mixin.py:109} WARNING -   File "/usr/local/lib/python3.7/multiprocessing/context.py", line 223, in _Popen
    return _default_context.get_context().Process._Popen(process_obj)
[2023-01-29 13:15:15,478] {logging_mixin.py:109} WARNING -   File "/usr/local/lib/python3.7/multiprocessing/context.py", line 277, in _Popen
    return Popen(process_obj)
[2023-01-29 13:15:15,479] {logging_mixin.py:109} WARNING -   File "/usr/local/lib/python3.7/multiprocessing/popen_fork.py", line 20, in __init__
    self._launch(process_obj)
[2023-01-29 13:15:15,479] {logging_mixin.py:109} WARNING -   File "/usr/local/lib/python3.7/multiprocessing/popen_fork.py", line 74, in _launch
    code = process_obj._bootstrap()
[2023-01-29 13:15:15,480] {logging_mixin.py:109} WARNING -   File "/usr/local/lib/python3.7/multiprocessing/process.py", line 297, in _bootstrap
    self.run()
[2023-01-29 13:15:15,480] {logging_mixin.py:109} WARNING -   File "/home/***/.local/lib/python3.7/site-packages/***/executors/local_executor.py", line 67, in run
    return super().run()
[2023-01-29 13:15:15,481] {logging_mixin.py:109} WARNING -   File "/usr/local/lib/python3.7/multiprocessing/process.py", line 99, in run
    self._target(*self._args, **self._kwargs)
[2023-01-29 13:15:15,481] {logging_mixin.py:109} WARNING -   File "/home/***/.local/lib/python3.7/site-packages/***/executors/local_executor.py", line 190, in do_work
    self.execute_work(key=key, command=command)
[2023-01-29 13:15:15,482] {logging_mixin.py:109} WARNING -   File "/home/***/.local/lib/python3.7/site-packages/***/executors/local_executor.py", line 84, in execute_work
    state = self._execute_work_in_fork(command)
[2023-01-29 13:15:15,482] {logging_mixin.py:109} WARNING -   File "/home/***/.local/lib/python3.7/site-packages/***/executors/local_executor.py", line 124, in _execute_work_in_fork
    args.func(args)
[2023-01-29 13:15:15,482] {logging_mixin.py:109} WARNING -   File "/home/***/.local/lib/python3.7/site-packages/***/cli/cli_parser.py", line 48, in command
    return func(*args, **kwargs)
[2023-01-29 13:15:15,483] {logging_mixin.py:109} WARNING -   File "/home/***/.local/lib/python3.7/site-packages/***/utils/cli.py", line 92, in wrapper
    return f(*args, **kwargs)
[2023-01-29 13:15:15,483] {logging_mixin.py:109} WARNING -   File "/home/***/.local/lib/python3.7/site-packages/***/cli/commands/task_command.py", line 298, in task_run
    _run_task_by_selected_method(args, dag, ti)
[2023-01-29 13:15:15,484] {logging_mixin.py:109} WARNING -   File "/home/***/.local/lib/python3.7/site-packages/***/cli/commands/task_command.py", line 105, in _run_task_by_selected_method
    _run_task_by_local_task_job(args, ti)
[2023-01-29 13:15:15,484] {logging_mixin.py:109} WARNING -   File "/home/***/.local/lib/python3.7/site-packages/***/cli/commands/task_command.py", line 163, in _run_task_by_local_task_job
    run_job.run()
[2023-01-29 13:15:15,485] {logging_mixin.py:109} WARNING -   File "/home/***/.local/lib/python3.7/site-packages/***/jobs/base_job.py", line 245, in run
    self._execute()
[2023-01-29 13:15:15,485] {logging_mixin.py:109} WARNING -   File "/home/***/.local/lib/python3.7/site-packages/***/jobs/local_task_job.py", line 103, in _execute
    self.task_runner.start()
[2023-01-29 13:15:15,485] {logging_mixin.py:109} WARNING -   File "/home/***/.local/lib/python3.7/site-packages/***/task/task_runner/standard_task_runner.py", line 41, in start
    self.process = self._start_by_fork()
[2023-01-29 13:15:15,486] {logging_mixin.py:109} WARNING -   File "/home/***/.local/lib/python3.7/site-packages/***/task/task_runner/standard_task_runner.py", line 85, in _start_by_fork
    args.func(args, dag=self.dag)
[2023-01-29 13:15:15,486] {logging_mixin.py:109} WARNING -   File "/home/***/.local/lib/python3.7/site-packages/***/cli/cli_parser.py", line 48, in command
    return func(*args, **kwargs)
[2023-01-29 13:15:15,487] {logging_mixin.py:109} WARNING -   File "/home/***/.local/lib/python3.7/site-packages/***/utils/cli.py", line 92, in wrapper
    return f(*args, **kwargs)
[2023-01-29 13:15:15,487] {logging_mixin.py:109} WARNING -   File "/home/***/.local/lib/python3.7/site-packages/***/cli/commands/task_command.py", line 298, in task_run
    _run_task_by_selected_method(args, dag, ti)
[2023-01-29 13:15:15,488] {logging_mixin.py:109} WARNING -   File "/home/***/.local/lib/python3.7/site-packages/***/cli/commands/task_command.py", line 107, in _run_task_by_selected_method
    _run_raw_task(args, ti)
[2023-01-29 13:15:15,488] {logging_mixin.py:109} WARNING -   File "/home/***/.local/lib/python3.7/site-packages/***/cli/commands/task_command.py", line 184, in _run_raw_task
    error_file=args.error_file,
[2023-01-29 13:15:15,489] {logging_mixin.py:109} WARNING -   File "/home/***/.local/lib/python3.7/site-packages/***/utils/session.py", line 70, in wrapper
    return func(*args, session=session, **kwargs)
[2023-01-29 13:15:15,489] {logging_mixin.py:109} WARNING -   File "/home/***/.local/lib/python3.7/site-packages/***/models/taskinstance.py", line 1329, in _run_raw_task
    self._execute_task_with_callbacks(context)
[2023-01-29 13:15:15,490] {logging_mixin.py:109} WARNING -   File "/home/***/.local/lib/python3.7/site-packages/***/models/taskinstance.py", line 1455, in _execute_task_with_callbacks
    result = self._execute_task(context, self.task)
[2023-01-29 13:15:15,490] {logging_mixin.py:109} WARNING -   File "/home/***/.local/lib/python3.7/site-packages/***/models/taskinstance.py", line 1511, in _execute_task
    result = execute_callable(context=context)
[2023-01-29 13:15:15,491] {logging_mixin.py:109} WARNING -   File "/home/***/.local/lib/python3.7/site-packages/***/operators/python.py", line 174, in execute
    return_value = self.execute_callable()
[2023-01-29 13:15:15,491] {logging_mixin.py:109} WARNING -   File "/home/***/.local/lib/python3.7/site-packages/***/operators/python.py", line 185, in execute_callable
    return self.python_callable(*self.op_args, **self.op_kwargs)
[2023-01-29 13:15:15,491] {logging_mixin.py:109} WARNING -   File "/opt/***/dags/data_ingestion_gcs_dag.py", line 62, in cast_parquet_columns
    logging.info('local_file',local_file)
[2023-01-29 13:15:15,492] {logging_mixin.py:109} WARNING -   File "/usr/local/lib/python3.7/logging/__init__.py", line 1992, in info
    root.info(msg, *args, **kwargs)
[2023-01-29 13:15:15,492] {logging_mixin.py:109} WARNING -   File "/usr/local/lib/python3.7/logging/__init__.py", line 1378, in info
    self._log(INFO, msg, args, **kwargs)
[2023-01-29 13:15:15,493] {logging_mixin.py:109} WARNING -   File "/usr/local/lib/python3.7/logging/__init__.py", line 1514, in _log
    self.handle(record)
[2023-01-29 13:15:15,493] {logging_mixin.py:109} WARNING -   File "/usr/local/lib/python3.7/logging/__init__.py", line 1524, in handle
    self.callHandlers(record)
[2023-01-29 13:15:15,494] {logging_mixin.py:109} WARNING -   File "/usr/local/lib/python3.7/logging/__init__.py", line 1586, in callHandlers
    hdlr.handle(record)
[2023-01-29 13:15:15,494] {logging_mixin.py:109} WARNING -   File "/usr/local/lib/python3.7/logging/__init__.py", line 894, in handle
    self.emit(record)
[2023-01-29 13:15:15,495] {logging_mixin.py:109} WARNING -   File "/home/***/.local/lib/python3.7/site-packages/***/utils/log/file_task_handler.py", line 67, in emit
    self.handler.emit(record)
[2023-01-29 13:15:15,495] {logging_mixin.py:109} WARNING - Message: 'local_file'
Arguments: ('/opt/***/fhv_tripdata_2019-01.parquet',)
[2023-01-29 13:15:17,625] {logging_mixin.py:109} WARNING - --- Logging error ---
[2023-01-29 13:15:17,633] {logging_mixin.py:109} WARNING - Traceback (most recent call last):
[2023-01-29 13:15:17,634] {logging_mixin.py:109} WARNING -   File "/usr/local/lib/python3.7/logging/__init__.py", line 1025, in emit
    msg = self.format(record)
[2023-01-29 13:15:17,634] {logging_mixin.py:109} WARNING -   File "/usr/local/lib/python3.7/logging/__init__.py", line 869, in format
    return fmt.format(record)
[2023-01-29 13:15:17,635] {logging_mixin.py:109} WARNING -   File "/usr/local/lib/python3.7/logging/__init__.py", line 608, in format
    record.message = record.getMessage()
[2023-01-29 13:15:17,636] {logging_mixin.py:109} WARNING -   File "/usr/local/lib/python3.7/logging/__init__.py", line 369, in getMessage
    msg = msg % self.args
[2023-01-29 13:15:17,636] {logging_mixin.py:109} WARNING - TypeError: not all arguments converted during string formatting
[2023-01-29 13:15:17,637] {logging_mixin.py:109} WARNING - Call stack:
[2023-01-29 13:15:17,660] {logging_mixin.py:109} WARNING -   File "/home/***/.local/bin/***", line 8, in <module>
    sys.exit(main())
[2023-01-29 13:15:17,676] {logging_mixin.py:109} WARNING -   File "/home/***/.local/lib/python3.7/site-packages/***/__main__.py", line 48, in main
    args.func(args)
[2023-01-29 13:15:17,676] {logging_mixin.py:109} WARNING -   File "/home/***/.local/lib/python3.7/site-packages/***/cli/cli_parser.py", line 48, in command
    return func(*args, **kwargs)
[2023-01-29 13:15:17,677] {logging_mixin.py:109} WARNING -   File "/home/***/.local/lib/python3.7/site-packages/***/utils/cli.py", line 92, in wrapper
    return f(*args, **kwargs)
[2023-01-29 13:15:17,677] {logging_mixin.py:109} WARNING -   File "/home/***/.local/lib/python3.7/site-packages/***/cli/commands/scheduler_command.py", line 75, in scheduler
    _run_scheduler_job(args=args)
[2023-01-29 13:15:17,678] {logging_mixin.py:109} WARNING -   File "/home/***/.local/lib/python3.7/site-packages/***/cli/commands/scheduler_command.py", line 46, in _run_scheduler_job
    job.run()
[2023-01-29 13:15:17,679] {logging_mixin.py:109} WARNING -   File "/home/***/.local/lib/python3.7/site-packages/***/jobs/base_job.py", line 245, in run
    self._execute()
[2023-01-29 13:15:17,680] {logging_mixin.py:109} WARNING -   File "/home/***/.local/lib/python3.7/site-packages/***/jobs/scheduler_job.py", line 620, in _execute
    self.executor.start()
[2023-01-29 13:15:17,680] {logging_mixin.py:109} WARNING -   File "/home/***/.local/lib/python3.7/site-packages/***/executors/local_executor.py", line 356, in start
    self.impl.start()
[2023-01-29 13:15:17,681] {logging_mixin.py:109} WARNING -   File "/home/***/.local/lib/python3.7/site-packages/***/executors/local_executor.py", line 298, in start
    worker.start()
[2023-01-29 13:15:17,681] {logging_mixin.py:109} WARNING -   File "/usr/local/lib/python3.7/multiprocessing/process.py", line 112, in start
    self._popen = self._Popen(self)
[2023-01-29 13:15:17,682] {logging_mixin.py:109} WARNING -   File "/usr/local/lib/python3.7/multiprocessing/context.py", line 223, in _Popen
    return _default_context.get_context().Process._Popen(process_obj)
[2023-01-29 13:15:17,683] {logging_mixin.py:109} WARNING -   File "/usr/local/lib/python3.7/multiprocessing/context.py", line 277, in _Popen
    return Popen(process_obj)
[2023-01-29 13:15:17,684] {logging_mixin.py:109} WARNING -   File "/usr/local/lib/python3.7/multiprocessing/popen_fork.py", line 20, in __init__
    self._launch(process_obj)
[2023-01-29 13:15:17,684] {logging_mixin.py:109} WARNING -   File "/usr/local/lib/python3.7/multiprocessing/popen_fork.py", line 74, in _launch
    code = process_obj._bootstrap()
[2023-01-29 13:15:17,685] {logging_mixin.py:109} WARNING -   File "/usr/local/lib/python3.7/multiprocessing/process.py", line 297, in _bootstrap
    self.run()
[2023-01-29 13:15:17,685] {logging_mixin.py:109} WARNING -   File "/home/***/.local/lib/python3.7/site-packages/***/executors/local_executor.py", line 67, in run
    return super().run()
[2023-01-29 13:15:17,686] {logging_mixin.py:109} WARNING -   File "/usr/local/lib/python3.7/multiprocessing/process.py", line 99, in run
    self._target(*self._args, **self._kwargs)
[2023-01-29 13:15:17,686] {logging_mixin.py:109} WARNING -   File "/home/***/.local/lib/python3.7/site-packages/***/executors/local_executor.py", line 190, in do_work
    self.execute_work(key=key, command=command)
[2023-01-29 13:15:17,686] {logging_mixin.py:109} WARNING -   File "/home/***/.local/lib/python3.7/site-packages/***/executors/local_executor.py", line 84, in execute_work
    state = self._execute_work_in_fork(command)
[2023-01-29 13:15:17,687] {logging_mixin.py:109} WARNING -   File "/home/***/.local/lib/python3.7/site-packages/***/executors/local_executor.py", line 124, in _execute_work_in_fork
    args.func(args)
[2023-01-29 13:15:17,688] {logging_mixin.py:109} WARNING -   File "/home/***/.local/lib/python3.7/site-packages/***/cli/cli_parser.py", line 48, in command
    return func(*args, **kwargs)
[2023-01-29 13:15:17,688] {logging_mixin.py:109} WARNING -   File "/home/***/.local/lib/python3.7/site-packages/***/utils/cli.py", line 92, in wrapper
    return f(*args, **kwargs)
[2023-01-29 13:15:17,689] {logging_mixin.py:109} WARNING -   File "/home/***/.local/lib/python3.7/site-packages/***/cli/commands/task_command.py", line 298, in task_run
    _run_task_by_selected_method(args, dag, ti)
[2023-01-29 13:15:17,689] {logging_mixin.py:109} WARNING -   File "/home/***/.local/lib/python3.7/site-packages/***/cli/commands/task_command.py", line 105, in _run_task_by_selected_method
    _run_task_by_local_task_job(args, ti)
[2023-01-29 13:15:17,690] {logging_mixin.py:109} WARNING -   File "/home/***/.local/lib/python3.7/site-packages/***/cli/commands/task_command.py", line 163, in _run_task_by_local_task_job
    run_job.run()
[2023-01-29 13:15:17,690] {logging_mixin.py:109} WARNING -   File "/home/***/.local/lib/python3.7/site-packages/***/jobs/base_job.py", line 245, in run
    self._execute()
[2023-01-29 13:15:17,691] {logging_mixin.py:109} WARNING -   File "/home/***/.local/lib/python3.7/site-packages/***/jobs/local_task_job.py", line 103, in _execute
    self.task_runner.start()
[2023-01-29 13:15:17,692] {logging_mixin.py:109} WARNING -   File "/home/***/.local/lib/python3.7/site-packages/***/task/task_runner/standard_task_runner.py", line 41, in start
    self.process = self._start_by_fork()
[2023-01-29 13:15:17,692] {logging_mixin.py:109} WARNING -   File "/home/***/.local/lib/python3.7/site-packages/***/task/task_runner/standard_task_runner.py", line 85, in _start_by_fork
    args.func(args, dag=self.dag)
[2023-01-29 13:15:17,692] {logging_mixin.py:109} WARNING -   File "/home/***/.local/lib/python3.7/site-packages/***/cli/cli_parser.py", line 48, in command
    return func(*args, **kwargs)
[2023-01-29 13:15:17,693] {logging_mixin.py:109} WARNING -   File "/home/***/.local/lib/python3.7/site-packages/***/utils/cli.py", line 92, in wrapper
    return f(*args, **kwargs)
[2023-01-29 13:15:17,693] {logging_mixin.py:109} WARNING -   File "/home/***/.local/lib/python3.7/site-packages/***/cli/commands/task_command.py", line 298, in task_run
    _run_task_by_selected_method(args, dag, ti)
[2023-01-29 13:15:17,694] {logging_mixin.py:109} WARNING -   File "/home/***/.local/lib/python3.7/site-packages/***/cli/commands/task_command.py", line 107, in _run_task_by_selected_method
    _run_raw_task(args, ti)
[2023-01-29 13:15:17,694] {logging_mixin.py:109} WARNING -   File "/home/***/.local/lib/python3.7/site-packages/***/cli/commands/task_command.py", line 184, in _run_raw_task
    error_file=args.error_file,
[2023-01-29 13:15:17,695] {logging_mixin.py:109} WARNING -   File "/home/***/.local/lib/python3.7/site-packages/***/utils/session.py", line 70, in wrapper
    return func(*args, session=session, **kwargs)
[2023-01-29 13:15:17,695] {logging_mixin.py:109} WARNING -   File "/home/***/.local/lib/python3.7/site-packages/***/models/taskinstance.py", line 1329, in _run_raw_task
    self._execute_task_with_callbacks(context)
[2023-01-29 13:15:17,696] {logging_mixin.py:109} WARNING -   File "/home/***/.local/lib/python3.7/site-packages/***/models/taskinstance.py", line 1455, in _execute_task_with_callbacks
    result = self._execute_task(context, self.task)
[2023-01-29 13:15:17,696] {logging_mixin.py:109} WARNING -   File "/home/***/.local/lib/python3.7/site-packages/***/models/taskinstance.py", line 1511, in _execute_task
    result = execute_callable(context=context)
[2023-01-29 13:15:17,697] {logging_mixin.py:109} WARNING -   File "/home/***/.local/lib/python3.7/site-packages/***/operators/python.py", line 174, in execute
    return_value = self.execute_callable()
[2023-01-29 13:15:17,697] {logging_mixin.py:109} WARNING -   File "/home/***/.local/lib/python3.7/site-packages/***/operators/python.py", line 185, in execute_callable
    return self.python_callable(*self.op_args, **self.op_kwargs)
[2023-01-29 13:15:17,698] {logging_mixin.py:109} WARNING -   File "/opt/***/dags/data_ingestion_gcs_dag.py", line 65, in cast_parquet_columns
    logging.info('table', table)
[2023-01-29 13:15:17,698] {logging_mixin.py:109} WARNING -   File "/usr/local/lib/python3.7/logging/__init__.py", line 1992, in info
    root.info(msg, *args, **kwargs)
[2023-01-29 13:15:17,698] {logging_mixin.py:109} WARNING -   File "/usr/local/lib/python3.7/logging/__init__.py", line 1378, in info
    self._log(INFO, msg, args, **kwargs)
[2023-01-29 13:15:17,699] {logging_mixin.py:109} WARNING -   File "/usr/local/lib/python3.7/logging/__init__.py", line 1514, in _log
    self.handle(record)
[2023-01-29 13:15:17,699] {logging_mixin.py:109} WARNING -   File "/usr/local/lib/python3.7/logging/__init__.py", line 1524, in handle
    self.callHandlers(record)
[2023-01-29 13:15:17,700] {logging_mixin.py:109} WARNING -   File "/usr/local/lib/python3.7/logging/__init__.py", line 1586, in callHandlers
    hdlr.handle(record)
[2023-01-29 13:15:17,700] {logging_mixin.py:109} WARNING -   File "/usr/local/lib/python3.7/logging/__init__.py", line 894, in handle
    self.emit(record)
[2023-01-29 13:15:17,701] {logging_mixin.py:109} WARNING -   File "/home/***/.local/lib/python3.7/site-packages/***/utils/log/file_task_handler.py", line 67, in emit
    self.handler.emit(record)
[2023-01-29 13:15:17,703] {logging_mixin.py:109} WARNING - Message: 'table'
Arguments: (pyarrow.Table
dispatching_base_num: string
pickup_datetime: timestamp[s]
dropOff_datetime: timestamp[s]
PUlocationID: int64
DOlocationID: int64
SR_Flag: int64
Affiliated_base_number: string,)
[2023-01-29 13:15:21,864] {python.py:175} INFO - Done. Returned value was: None
[2023-01-29 13:15:21,879] {taskinstance.py:1277} INFO - Marking task as SUCCESS. dag_id=data_ingestion_gcs_dag, task_id=cast_parquet_columns_task, execution_date=20190101T000000, start_date=20230129T131515, end_date=20230129T131521
[2023-01-29 13:15:22,212] {local_task_job.py:154} INFO - Task exited with return code 0
[2023-01-29 13:15:22,241] {local_task_job.py:264} INFO - 0 downstream tasks scheduled from follow-on schedule check
