[2023-01-24 11:31:02,577] {taskinstance.py:1032} INFO - Dependencies all met for <TaskInstance: data_ingestion_zone_dag.download_dataset_task manual__2023-01-24T11:25:53.842431+00:00 [queued]>
[2023-01-24 11:31:02,598] {taskinstance.py:1032} INFO - Dependencies all met for <TaskInstance: data_ingestion_zone_dag.download_dataset_task manual__2023-01-24T11:25:53.842431+00:00 [queued]>
[2023-01-24 11:31:02,598] {taskinstance.py:1238} INFO - 
--------------------------------------------------------------------------------
[2023-01-24 11:31:02,598] {taskinstance.py:1239} INFO - Starting attempt 2 of 3
[2023-01-24 11:31:02,598] {taskinstance.py:1240} INFO - 
--------------------------------------------------------------------------------
[2023-01-24 11:31:02,620] {taskinstance.py:1259} INFO - Executing <Task(BashOperator): download_dataset_task> on 2023-01-24 11:25:53.842431+00:00
[2023-01-24 11:31:02,632] {standard_task_runner.py:52} INFO - Started process 4453 to run task
[2023-01-24 11:31:02,639] {standard_task_runner.py:76} INFO - Running: ['***', 'tasks', 'run', 'data_ingestion_zone_dag', 'download_dataset_task', 'manual__2023-01-24T11:25:53.842431+00:00', '--job-id', '164', '--raw', '--subdir', 'DAGS_FOLDER/data_ingestion_zone_dag.py', '--cfg-path', '/tmp/tmph0fsh944', '--error-file', '/tmp/tmpee03bbu0']
[2023-01-24 11:31:02,641] {standard_task_runner.py:77} INFO - Job 164: Subtask download_dataset_task
[2023-01-24 11:31:02,740] {logging_mixin.py:109} INFO - Running <TaskInstance: data_ingestion_zone_dag.download_dataset_task manual__2023-01-24T11:25:53.842431+00:00 [running]> on host 07340d4b95ab
[2023-01-24 11:31:02,821] {taskinstance.py:1426} INFO - Exporting the following env vars:
AIRFLOW_CTX_DAG_OWNER=***
AIRFLOW_CTX_DAG_ID=data_ingestion_zone_dag
AIRFLOW_CTX_TASK_ID=download_dataset_task
AIRFLOW_CTX_EXECUTION_DATE=2023-01-24T11:25:53.842431+00:00
AIRFLOW_CTX_DAG_RUN_ID=manual__2023-01-24T11:25:53.842431+00:00
[2023-01-24 11:31:02,822] {subprocess.py:62} INFO - Tmp dir root location: 
 /tmp
[2023-01-24 11:31:02,822] {subprocess.py:74} INFO - Running command: ['bash', '-c', 'curl -sSLf https://d37ci6vzurychx.cloudfront.net/taxi+_zone_lookup.csv > /opt/***/taxi+_zone_lookup.csv']
[2023-01-24 11:31:02,837] {subprocess.py:85} INFO - Output:
[2023-01-24 11:31:03,705] {subprocess.py:89} INFO - curl: (22) The requested URL returned error: 403
[2023-01-24 11:31:03,707] {subprocess.py:93} INFO - Command exited with return code 22
[2023-01-24 11:31:03,727] {taskinstance.py:1700} ERROR - Task failed with exception
Traceback (most recent call last):
  File "/home/airflow/.local/lib/python3.7/site-packages/airflow/models/taskinstance.py", line 1329, in _run_raw_task
    self._execute_task_with_callbacks(context)
  File "/home/airflow/.local/lib/python3.7/site-packages/airflow/models/taskinstance.py", line 1455, in _execute_task_with_callbacks
    result = self._execute_task(context, self.task)
  File "/home/airflow/.local/lib/python3.7/site-packages/airflow/models/taskinstance.py", line 1511, in _execute_task
    result = execute_callable(context=context)
  File "/home/airflow/.local/lib/python3.7/site-packages/airflow/operators/bash.py", line 188, in execute
    f'Bash command failed. The command returned a non-zero exit code {result.exit_code}.'
airflow.exceptions.AirflowException: Bash command failed. The command returned a non-zero exit code 22.
[2023-01-24 11:31:03,736] {taskinstance.py:1277} INFO - Marking task as UP_FOR_RETRY. dag_id=data_ingestion_zone_dag, task_id=download_dataset_task, execution_date=20230124T112553, start_date=20230124T113102, end_date=20230124T113103
[2023-01-24 11:31:03,755] {standard_task_runner.py:92} ERROR - Failed to execute job 164 for task download_dataset_task
Traceback (most recent call last):
  File "/home/airflow/.local/lib/python3.7/site-packages/airflow/task/task_runner/standard_task_runner.py", line 85, in _start_by_fork
    args.func(args, dag=self.dag)
  File "/home/airflow/.local/lib/python3.7/site-packages/airflow/cli/cli_parser.py", line 48, in command
    return func(*args, **kwargs)
  File "/home/airflow/.local/lib/python3.7/site-packages/airflow/utils/cli.py", line 92, in wrapper
    return f(*args, **kwargs)
  File "/home/airflow/.local/lib/python3.7/site-packages/airflow/cli/commands/task_command.py", line 298, in task_run
    _run_task_by_selected_method(args, dag, ti)
  File "/home/airflow/.local/lib/python3.7/site-packages/airflow/cli/commands/task_command.py", line 107, in _run_task_by_selected_method
    _run_raw_task(args, ti)
  File "/home/airflow/.local/lib/python3.7/site-packages/airflow/cli/commands/task_command.py", line 184, in _run_raw_task
    error_file=args.error_file,
  File "/home/airflow/.local/lib/python3.7/site-packages/airflow/utils/session.py", line 70, in wrapper
    return func(*args, session=session, **kwargs)
  File "/home/airflow/.local/lib/python3.7/site-packages/airflow/models/taskinstance.py", line 1329, in _run_raw_task
    self._execute_task_with_callbacks(context)
  File "/home/airflow/.local/lib/python3.7/site-packages/airflow/models/taskinstance.py", line 1455, in _execute_task_with_callbacks
    result = self._execute_task(context, self.task)
  File "/home/airflow/.local/lib/python3.7/site-packages/airflow/models/taskinstance.py", line 1511, in _execute_task
    result = execute_callable(context=context)
  File "/home/airflow/.local/lib/python3.7/site-packages/airflow/operators/bash.py", line 188, in execute
    f'Bash command failed. The command returned a non-zero exit code {result.exit_code}.'
airflow.exceptions.AirflowException: Bash command failed. The command returned a non-zero exit code 22.
[2023-01-24 11:31:03,779] {local_task_job.py:154} INFO - Task exited with return code 1
[2023-01-24 11:31:03,826] {local_task_job.py:264} INFO - 0 downstream tasks scheduled from follow-on schedule check
