[2023-01-24 11:31:33,717] {taskinstance.py:1032} INFO - Dependencies all met for <TaskInstance: data_ingestion_zone_dag.download_dataset_task manual__2023-01-24T11:26:30.166492+00:00 [queued]>
[2023-01-24 11:31:33,729] {taskinstance.py:1032} INFO - Dependencies all met for <TaskInstance: data_ingestion_zone_dag.download_dataset_task manual__2023-01-24T11:26:30.166492+00:00 [queued]>
[2023-01-24 11:31:33,730] {taskinstance.py:1238} INFO - 
--------------------------------------------------------------------------------
[2023-01-24 11:31:33,730] {taskinstance.py:1239} INFO - Starting attempt 2 of 2
[2023-01-24 11:31:33,730] {taskinstance.py:1240} INFO - 
--------------------------------------------------------------------------------
[2023-01-24 11:31:33,743] {taskinstance.py:1259} INFO - Executing <Task(BashOperator): download_dataset_task> on 2023-01-24 11:26:30.166492+00:00
[2023-01-24 11:31:33,751] {standard_task_runner.py:52} INFO - Started process 4516 to run task
[2023-01-24 11:31:33,758] {standard_task_runner.py:76} INFO - Running: ['***', 'tasks', 'run', 'data_ingestion_zone_dag', 'download_dataset_task', 'manual__2023-01-24T11:26:30.166492+00:00', '--job-id', '165', '--raw', '--subdir', 'DAGS_FOLDER/data_ingestion_zone_dag.py', '--cfg-path', '/tmp/tmpndj894xq', '--error-file', '/tmp/tmpfhtf24_5']
[2023-01-24 11:31:33,759] {standard_task_runner.py:77} INFO - Job 165: Subtask download_dataset_task
[2023-01-24 11:31:33,826] {logging_mixin.py:109} INFO - Running <TaskInstance: data_ingestion_zone_dag.download_dataset_task manual__2023-01-24T11:26:30.166492+00:00 [running]> on host 07340d4b95ab
[2023-01-24 11:31:33,897] {taskinstance.py:1426} INFO - Exporting the following env vars:
AIRFLOW_CTX_DAG_OWNER=***
AIRFLOW_CTX_DAG_ID=data_ingestion_zone_dag
AIRFLOW_CTX_TASK_ID=download_dataset_task
AIRFLOW_CTX_EXECUTION_DATE=2023-01-24T11:26:30.166492+00:00
AIRFLOW_CTX_DAG_RUN_ID=manual__2023-01-24T11:26:30.166492+00:00
[2023-01-24 11:31:33,899] {subprocess.py:62} INFO - Tmp dir root location: 
 /tmp
[2023-01-24 11:31:33,900] {subprocess.py:74} INFO - Running command: ['bash', '-c', 'curl -sSLf https://d37ci6vzurychx.cloudfront.net/taxi+_zone_lookup.csv > /opt/***/taxi+_zone_lookup.csv']
[2023-01-24 11:31:33,915] {subprocess.py:85} INFO - Output:
[2023-01-24 11:31:34,635] {subprocess.py:89} INFO - curl: (22) The requested URL returned error: 403
[2023-01-24 11:31:34,638] {subprocess.py:93} INFO - Command exited with return code 22
[2023-01-24 11:31:34,656] {taskinstance.py:1700} ERROR - Task failed with exception
Traceback (most recent call last):
  File "/home/airflow/.local/lib/python3.7/site-packages/airflow/models/taskinstance.py", line 1329, in _run_raw_task
    self._execute_task_with_callbacks(context)
  File "/home/airflow/.local/lib/python3.7/site-packages/airflow/models/taskinstance.py", line 1455, in _execute_task_with_callbacks
    result = self._execute_task(context, self.task)
  File "/home/airflow/.local/lib/python3.7/site-packages/airflow/models/taskinstance.py", line 1511, in _execute_task
    result = execute_callable(context=context)
  File "/home/airflow/.local/lib/python3.7/site-packages/airflow/operators/bash.py", line 188, in execute
    f'Bash command failed. The command returned a non-zero exit code {result.exit_code}.'
airflow.exceptions.AirflowException: Bash command failed. The command returned a non-zero exit code 22.
[2023-01-24 11:31:34,664] {taskinstance.py:1277} INFO - Marking task as FAILED. dag_id=data_ingestion_zone_dag, task_id=download_dataset_task, execution_date=20230124T112630, start_date=20230124T113133, end_date=20230124T113134
[2023-01-24 11:31:34,682] {standard_task_runner.py:92} ERROR - Failed to execute job 165 for task download_dataset_task
Traceback (most recent call last):
  File "/home/airflow/.local/lib/python3.7/site-packages/airflow/task/task_runner/standard_task_runner.py", line 85, in _start_by_fork
    args.func(args, dag=self.dag)
  File "/home/airflow/.local/lib/python3.7/site-packages/airflow/cli/cli_parser.py", line 48, in command
    return func(*args, **kwargs)
  File "/home/airflow/.local/lib/python3.7/site-packages/airflow/utils/cli.py", line 92, in wrapper
    return f(*args, **kwargs)
  File "/home/airflow/.local/lib/python3.7/site-packages/airflow/cli/commands/task_command.py", line 298, in task_run
    _run_task_by_selected_method(args, dag, ti)
  File "/home/airflow/.local/lib/python3.7/site-packages/airflow/cli/commands/task_command.py", line 107, in _run_task_by_selected_method
    _run_raw_task(args, ti)
  File "/home/airflow/.local/lib/python3.7/site-packages/airflow/cli/commands/task_command.py", line 184, in _run_raw_task
    error_file=args.error_file,
  File "/home/airflow/.local/lib/python3.7/site-packages/airflow/utils/session.py", line 70, in wrapper
    return func(*args, session=session, **kwargs)
  File "/home/airflow/.local/lib/python3.7/site-packages/airflow/models/taskinstance.py", line 1329, in _run_raw_task
    self._execute_task_with_callbacks(context)
  File "/home/airflow/.local/lib/python3.7/site-packages/airflow/models/taskinstance.py", line 1455, in _execute_task_with_callbacks
    result = self._execute_task(context, self.task)
  File "/home/airflow/.local/lib/python3.7/site-packages/airflow/models/taskinstance.py", line 1511, in _execute_task
    result = execute_callable(context=context)
  File "/home/airflow/.local/lib/python3.7/site-packages/airflow/operators/bash.py", line 188, in execute
    f'Bash command failed. The command returned a non-zero exit code {result.exit_code}.'
airflow.exceptions.AirflowException: Bash command failed. The command returned a non-zero exit code 22.
[2023-01-24 11:31:34,694] {local_task_job.py:154} INFO - Task exited with return code 1
[2023-01-24 11:31:34,742] {local_task_job.py:264} INFO - 0 downstream tasks scheduled from follow-on schedule check
